<mujoco model="Murdoc">

    <compiler inertiafromgeom='true' angle='degree'/>
    <option gravity='0 0 -9.78'/>
    <asset>
		<!-- Sets sky rendering
		-->
        <texture type="skybox" builtin="gradient" width="100" height="100" rgb1="0 0 0"
            rgb2="0 0 0"/>
		<!-- Not clear to me where this is used yet
		-->
        <texture name="texgeom" type="cube" builtin="flat" mark="cross" width="127" height="1278"
            rgb1="0.1 0.8 0.1" rgb2="0.8 0.6 0.4" markrgb="1 1 1" random="0.01"/>
		<!-- Sets floor rendering
		-->
        <texture name="texplane" type="2d" builtin="checker" rgb1=".2 .3 .4" rgb2=".1 0.15 0.2"
            width="1000" height="1000"/>
        <texture name='bone_texture' type="cube" file="$resourcesDir$/Bone.png"/>
		<!-- Create materials based on textures above
		-->
        <material name='MatPlane' reflectance='0.5' texture="texplane"/>
        <material name='geom' texture="texgeom" texuniform="true"/>
        <material name='bone' texture='bone_texture' reflectance='0' texuniform='true' specular='0' shininess='0'/>

        <mesh file="$resourcesDir$/Mobile Foot/Pelvis.stl" scale='$meshScale$ $meshScale$ $meshScale$' />
        <mesh file="$resourcesDir$/Mobile Foot/Femur_Left.stl" scale='$meshScale$ $meshScale$ $meshScale$' />
        <mesh file="$resourcesDir$/Mobile Foot/Femur_Right.stl" scale='$meshScale$ $meshScale$ $meshScale$' />
        <mesh file="$resourcesDir$/Mobile Foot/Shin_Left.stl" scale='$meshScale$ $meshScale$ $meshScale$' />
        <mesh file="$resourcesDir$/Mobile Foot/Shin_Right.stl" scale='$meshScale$ $meshScale$ $meshScale$' />
        <mesh file="$resourcesDir$/Mobile Foot/Foot_Left.stl" scale='$meshScale$ $meshScale$ $meshScale$' />
        <mesh file="$resourcesDir$/Mobile Foot/Foot_Right.stl" scale='$meshScale$ $meshScale$ $meshScale$' />
        <mesh file="$resourcesDir$/Mobile Foot/Toes_Left.stl" scale='$meshScale$ $meshScale$ $meshScale$' />
        <mesh file="$resourcesDir$/Mobile Foot/Toes_Right.stl" scale='$meshScale$ $meshScale$ $meshScale$' />

    </asset>

	<default>
    <site size='0.5e-3 0.5e-3 0.5e-3' rgba='1 0 0 0'/>
    <!--<geom solref = '0.02 .04' density = '2e3'/>-->
    <default class='Hip_Left:x'>
      <joint type='hinge' axis='0 1 0' ref='0' range='-120 -40' limited='true' armature='0.0001' stiffness='0' springref='0'/>
		</default>
		<default class='Hip_Left:y'>
            <joint type='hinge' axis='0 1 0' range='-50 20' damping='5' limited='true' stiffness='0' armature='0.0080' />
		</default>
		<default class='Hip_Left:z'>
            <joint type='hinge' axis='0 0 1' range='-40 40' damping='5' limited='true' stiffness='0' armature='0.0080' />
		</default>
		<default class = 'Knee_Left:x'>
			<joint type='hinge' axis='1 0 0' range='10  120' limited='true'  armature='0.0006'  stiffness='0' springref='0'/>
		</default>
		<default class = 'Knee_Left:y'>
			<joint type='hinge' axis='1 0 0' range='-40 120' limited='true'  armature='0.0006'  stiffness='0' springref='0'/>
		</default>
		<default class = 'Ankle_Left:x'>
			<joint type='hinge' axis='1 0 0' pos='0 0 0' range='-50 60' limited='true'  armature='0.0006' stiffness='0' springref='0'/>
		</default>
		<default class = 'Ankle_Left:y'>
			<joint type='hinge' axis='0 1 0' pos='0 0 0' range='-25 10' limited='true'  armature='0.0006' stiffness='0' springref='0'/>
		</default>
		<default class = 'Toes_Left:x'>
			<joint type='hinge' axis='1 0 0' pos='0 0 0' range='-120 20' limited='true'  armature='0.0006' stiffness='0' springref='0'/>
		</default>

  <default class='Hip_Right:x'>
    <joint type='hinge' axis='0 1 0' ref='0' range='-120 -40' limited='true' armature='0.0001' stiffness='0' springref='0'/>
  </default>
  <default class='Hip_Right:y'>
          <joint type='hinge' axis='0 1 0' range='-20 50' damping='5' limited='true' stiffness='0' armature='0.0080' />
  </default>
  <default class='Hip_Right:z'>
          <joint type='hinge' axis='0 0 1' range='-40 40' damping='5' limited='true' stiffness='0' armature='0.0080' />
  </default>
  <default class = 'Knee_Right:x'>
    <joint type='hinge' axis='1 0 0' range='10 120' limited='true'  armature='0.0006'  stiffness='0' springref='0'/>
  </default>
  <default class = 'Knee_Right:y'>
    <joint type='hinge' axis='1 0 0' range='-40 120' limited='true'  armature='0.0006'  stiffness='0' springref='0'/>
  </default>
  <default class = 'Ankle_Right:x'>
    <joint type='hinge' axis='1 0 0' pos='0 0 0' range='-50 60' limited='true'  armature='0.0006' stiffness='0' springref='0'/>
  </default>
  <default class = 'Ankle_Right:y'>
    <joint type='hinge' axis='0 1 0' pos='0 0 0' range='-25 10' limited='true'  armature='0.0006' stiffness='0' springref='0'/>
  </default>
  <default class = 'Toes_Right:x'>
    <joint type='hinge' axis='1 0 0' pos='0 0 0' range='-120 20' limited='true'  armature='0.0006' stiffness='0' springref='0'/>
  </default>
	</default>

	<worldbody>
    <light directional='false' castshadow = 'false' diffuse='1 1 1' specular='0 0 0' pos='0 0 150' dir='0 0 -1'/>
      <!--
      <body name = 'Init' pos = '0 0 0' euler = '0 0 0'>
          <site name="C_Init" pos='-0.022000 -0.035000 0.015000' rgba='1 0 0 1' size='15e-3'/>
          <site name="GT_Init" pos='-0.038383 0.038689 -0.027012' rgba='0 1 0 1' size='15e-3'/>
          <site name="K_Init" pos='-0.048703 -0.061385 -0.141855' rgba='0 0 1 1' size='15e-3'/>
          <site name="MT_Init" pos='-0.052363 0.055734 -0.263889' rgba='0 1 1 1' size='15e-3'/>
          <site name="M_Init" pos='-0.036526 0.099504 -0.205868' rgba='1 1 0 1' size='15e-3'/>
      </body>
    -->
    <!--
    <body name='Lower_Body' pos='0 0 0' euler='0 0 0'>-->
  
	<body name='Treadmill'>
	<geom name = 'Treadmill' type = 'box' size = '10. 0.5 5e-1' pos = '-9. 0 -0.9' rgba="0.3 0.3 0.3 0.3"/> 
	<site name="Treadmill" pos='-9. 0 -0.5' rgba='0 1 1 0' size='5e-3'/>
	</body>
	
    <!--<camera name = 'Sagittal_Right_Corridor' mode = 'fixed' pos = '-6 -.1 -.2' euler = '-90 -85 180' fovy = '15'/>
    <camera name = 'Sagittal_Right_Treadmill' mode = 'fixed' pos = '-4 0 .5' euler = '0 -80 -90' fovy = '10'/>
    <camera name = 'Sagittal_Left_Corridor' mode = 'fixed' pos = '-4 -.1 -.2' euler = '-90 -85 180' fovy = '15'/>
    <camera name = 'Sagittal_Left_Treadmill' mode = 'fixed' pos = '4 0 .5' euler = '0 80 90' fovy = '10'/>-->
    <camera name = 'Sagittal_Right' mode = 'track' pos = '0 8 0' euler = '90 180 0' fovy = '10'/>
    <camera name = 'Sagittal_Left' mode = 'track' pos = '0 -8 0' euler = '90 0 0' fovy = '10'/>
    <camera name = 'Frontal' mode = 'track' pos = '-8 0 0' euler = '90 -90 0' fovy = '10'/>
    <camera name = 'Back' mode = 'track' pos = '8 0 0' euler = '90 90 0' fovy = '10'/>
    <camera name = 'Up' mode = 'track' pos = '0 0 8' euler = '0 0 90' fovy = '10'/>
	
	<geom name = "T11" pos='-0.4 0 0' type = 'sphere' size = '5e-3' rgba='0.7 0.3 0.9 1' density = '0.0002'/>
	
	<geom name = "T21" pos='0.01 0 0' type = 'sphere' size = '5e-3' rgba='0.7 0.3 0.9 1' density = '0.0002'/>

    <body name = 'Monkey' pos='0 0 0' euler='0 0 0'>
    <joint name='World' type = 'free'/>
    <geom name = "T12" pos='$T12:x$	$T12:y$	$T12:z$' type = 'sphere' size = '5e-3' rgba='0 1 1 1' density = '0.0002'/>
	<geom name = "T22" pos='0 0 0' type = 'sphere' size = '5e-3' rgba='0.7 0.3 0.9 1' density = '0.0002'/>
    <body name='Pelvis' pos='0 0 0' euler='0 0 0'>
		
     <site name="BF_Pelvis_Left" pos='$BF_Pelvis_Left:x$	$BF_Pelvis_Left:y$	$BF_Pelvis_Left:z$' rgba='1 0 0 0'/>
     <site name="RF_Pelvis_Left" pos='$RF_Pelvis_Left:x$	$RF_Pelvis_Left:y$	$RF_Pelvis_Left:z$' rgba='1 0 0 0'/>
     <site name="GMED_Pelvis_Left" pos='$GMED_Pelvis_Left:x$	$GMED_Pelvis_Left:y$	$GMED_Pelvis_Left:z$' rgba='1 0 0 0'/>
     <site name="IL_Pelvis_Left" pos='$IL_Pelvis_Left:x$	$IL_Pelvis_Left:y$	$IL_Pelvis_Left:z$' rgba='1 0 0 0'/>
     <site name="GMAX_Pelvis_Left" pos='$GMAX_Pelvis_Left:x$	$GMAX_Pelvis_Left:y$	$GMAX_Pelvis_Left:z$' rgba='1 0 0 0'/>

     <site name="GMED_Pelvis_Right" pos='$GMED_Pelvis_Right:x$	$GMED_Pelvis_Right:y$	$GMED_Pelvis_Right:z$' rgba='0 0 1 0'/>
     <site name="IL_Pelvis_Right" pos='$IL_Pelvis_Right:x$	$IL_Pelvis_Right:y$	$IL_Pelvis_Right:z$' rgba='0 0 1 0'/>
     <site name="RF_Pelvis_Right" pos='$RF_Pelvis_Right:x$	$RF_Pelvis_Right:y$	$RF_Pelvis_Right:z$' rgba='0 0 1 0'/>
     <site name="BF_Pelvis_Right" pos='$BF_Pelvis_Right:x$	$BF_Pelvis_Right:y$	$BF_Pelvis_Right:z$' rgba='0 0 1 0'/>
     <site name="GMAX_Pelvis_Right" pos='$GMAX_Pelvis_Right:x$	$GMAX_Pelvis_Right:y$	$GMAX_Pelvis_Right:z$' rgba='0 0 1 0'/>

     <site name="C_Right" group='1' pos='$C_Right:x$	$C_Right:y$	$C_Right:z$' rgba='1 1 1 1' size='5e-3'/>
     <site name="C_Left" group='1' pos='$C_Left:x$	$C_Left:y$	$C_Left:z$' rgba='1 1 1 1' size='5e-3'/>

     <geom type='mesh' mesh='Pelvis'  pos='0 0 0' euler='0 0 0' rgba='0.651 0.623 0.572 1'/>

      <body name='GT_Holder_Right' pos='0 0 0' euler='0 0 0'>
        <site name="GT_Right" group='1' pos='$GT_Right:x$	$GT_Right:y$	$GT_Right:z$' rgba='1 1 0 1' size='5e-3'/>
      </body>

    <body name='Leg_Right' pos='0 0 0' euler='0 0 0'>

      <joint name='Hip_Right:x' class='Hip_Right:x' axis='$Hip_Right:x:x$	$Hip_Right:x:y$	$Hip_Right:x:z$' ref = '-90' pos='$Hip_Right:o:x$	$Hip_Right:o:y$	$Hip_Right:o:z$'/>
      <joint name='Hip_Right:y' class='Hip_Right:y' axis='$Hip_Right:y:x$	$Hip_Right:y:y$	$Hip_Right:y:z$' ref = '-10' pos='$Hip_Right:o:x$	$Hip_Right:o:y$	$Hip_Right:o:z$'/>
      <joint name='Hip_Right:z' class='Hip_Right:z' axis='$Hip_Right:z:x$	$Hip_Right:z:y$	$Hip_Right:z:z$' ref = '0' pos='$Hip_Right:o:x$	$Hip_Right:o:y$	$Hip_Right:o:z$'/>

  	  <geom type='mesh' mesh='Femur_Right'  pos='0 0 0' euler='0 0 0' rgba='0.651 0.623 0.572 1'/>
	  
	  <geom type="cylinder" name='Knee_FR' density='0' fromto='-0.18 0.1 0.037  -0.2 0.0 0.037' size="0.015" rgba=".3 .9 .3 0."/>	  
	  <site name='slide1' pos='-0.19 0.5 0.052'/>

      <site name="GMED_Femur_Right" pos='$GMED_Femur_Right:x$	$GMED_Femur_Right:y$	$GMED_Femur_Right:z$' rgba='0 0 1 0'/>

      <site name="IL_Femur_Right" pos='$IL_Femur_Right:x$	$IL_Femur_Right:y$	$IL_Femur_Right:z$' rgba='0 0 1 0'/>
      <site name="IL_Front_Right" pos='$IL_Front_Right:x$	$IL_Front_Right:y$	$IL_Front_Right:z$' rgba='0 0 1 0'/>

      <site name="VAS_Femur_Right" pos='$VAS_Femur_Right:x$	$VAS_Femur_Right:y$	$VAS_Femur_Right:z$' rgba='0 0 1 0'/>
      <site name="GAS_Femur_Right" pos='$GAS_Femur_Right:x$	$GAS_Femur_Right:y$	$GAS_Femur_Right:z$' rgba='0 0 1 0'/>
      <site name="GMAX_Femur_Right" pos='$GMAX_Femur_Right:x$	$GMAX_Femur_Right:y$	$GMAX_Femur_Right:z$' rgba='0 0 1 0'/>

      <site name="K_Right" pos='$K_Right:x$	$K_Right:y$	$K_Right:z$' rgba='1 0 0 1' size='5e-3'/>

  	  <body name='Shin_Right' pos='0 0 0' euler='0 0 0'>
		  
		  <geom type="cylinder" name='Knee_FR2' density='0' fromto='-0.205 0.1 0.027  -0.225 0.0 0.027' size="0.012" rgba=".3 .9 .3 0."/>
	         <site name='slide2' pos='-0.215 0.05 0.015'/>
			 
          <geom type='mesh' mesh='Shin_Right'  pos='0 0 0' euler='0 0 0' rgba='0.651 0.623 0.572 1'/>

          <site name="VAS_Tibia_Right" pos='$VAS_Tibia_Right:x$	$VAS_Tibia_Right:y$	$VAS_Tibia_Right:z$' rgba='0 0 1 0'/>
          <site name="TA_Tibia_Right" pos='$TA_Tibia_Right:x$	$TA_Tibia_Right:y$	$TA_Tibia_Right:z$' rgba='0 0 1 0'/>
          <site name="SOL_Tibia_Right" pos='$SOL_Tibia_Right:x$	$SOL_Tibia_Right:y$	$SOL_Tibia_Right:z$' rgba='0 0 1 0'/>
          <site name="RF_Tibia_Right" pos='$RF_Tibia_Right:x$	$RF_Tibia_Right:y$	$RF_Tibia_Right:z$' rgba='0 0 1 0'/>
          <site name="BF_Tibia_Right" pos='$BF_Tibia_Right:x$	$BF_Tibia_Right:y$	$BF_Tibia_Right:z$' rgba='0 0 1 0'/>
		  <site name="EDL_Tibia_Right" pos='$EDL_Tibia_Right:x$	$EDL_Tibia_Right:y$	$EDL_Tibia_Right:z$' rgba='0 0 1 0'/>
		  <site name="FHL_Shin_Right" pos='$FHL_Shin_Right:x$	$FHL_Shin_Right:y$	$FHL_Shin_Right:z$' rgba='0 0 1 0'/>

          <joint name='Knee_Right:x' class='Knee_Right:x' axis='$Knee_Right:x:x$	$Knee_Right:x:y$	$Knee_Right:x:z$' ref='10' pos='$Knee_Right:o:x$	$Knee_Right:o:y$	$Knee_Right:o:z$'/>

  				<body name='Foot_Right' pos='0 0 0' >

            <geom type='mesh' mesh='Foot_Right'  pos='0 0 0' euler='0 0 0' rgba='0.651 0.623 0.572 1'/>	
			
            <site name="M_Right" pos='$M_Right:x$	$M_Right:y$	$M_Right:z$' rgba='0.5 0.5 0.5 1' size='5e-3'/>
            <site name="MT_Right" pos='$MT_Right:x$	$MT_Right:y$	$MT_Right:z$' rgba='0 0 1 1' size='5e-3'/>

            <site name="TA_Ankle_Right" pos='$TA_Ankle_Right:x$	$TA_Ankle_Right:y$	$TA_Ankle_Right:z$' rgba='0 0 1 0'/>
            <site name="SOL_Ankle_Right" pos='$SOL_Ankle_Right:x$	$SOL_Ankle_Right:y$	$SOL_Ankle_Right:z$' rgba='0 0 1 0'/>
            <site name="GAS_Ankle_Right" pos='$GAS_Ankle_Right:x$	$GAS_Ankle_Right:y$	$GAS_Ankle_Right:z$' rgba='0 0 1 0'/>
			<site name="EDL_Ankle_Right" pos='$EDL_Ankle_Right:x$	$EDL_Ankle_Right:y$	$EDL_Ankle_Right:z$' rgba='0 0 1 0'/>
			<site name="FHL_Ankle_Right" pos='$FHL_Ankle_Right:x$	$FHL_Ankle_Right:y$	$FHL_Ankle_Right:z$' rgba='0 0 1 0'/>
			<site name="Site_EDL_Right" pos='$Site_EDL_Right:x$	$Site_EDL_Right:y$	$Site_EDL_Right:z$' rgba='0 0 1 0'/>
			<site name="Site_FHL_Right" pos='$Site_FHL_Right:x$	$Site_FHL_Right:y$	$Site_FHL_Right:z$' rgba='0 0 1 0'/>
			
			<geom type="cylinder" name='Ankle_EDL_Right' density='0' fromto='-0.44 0.13 -0.004  -0.42 0.03 -0.004' size="0.008" rgba=".3 .9 .3 0."/>
	         <site name='slide3' pos='$EDL_Ankle_Right:x$	$EDL_Ankle_Right:y$	$EDL_Ankle_Right:z$'/>	
			 
			 <geom type="cylinder" name='Ankle_FHL_Right' density='0' fromto='-0.41 0.13 -0.018  -0.39 0.03 -0.018' size="0.01" rgba=".3 .9 .3 0."/>
	         <site name='slide4' pos='$FHL_Ankle_Right:x$	$FHL_Ankle_Right:y$	$FHL_Ankle_Right:z$'/>

            <joint name='Ankle_Right:x' class='Ankle_Right:x' axis='$Ankle_Right:x:x$	$Ankle_Right:x:y$	$Ankle_Right:x:z$'  ref='45' pos='$Ankle_Right:o:x$	$Ankle_Right:o:y$	$Ankle_Right:o:z$'/>
            <joint name='Ankle_Right:y' class='Ankle_Right:y' axis='$Ankle_Right:y:x$	$Ankle_Right:y:y$	$Ankle_Right:y:z$'  ref='0'  pos='$Ankle_Right:o:x$	$Ankle_Right:o:y$	$Ankle_Right:o:z$'/>
            
			<body name = 'Sole_Right'>
            <geom name = 'Sole_Right' pos='-0.45 0.06 -0.02' type = 'ellipsoid' size = '5.5e-2 2.6e-2 5e-4' rgba = '1 0.5 0.5 0' euler = '0 20 12' density='0.'/>
            <site name="Sole_Tip_Right" pos='-0.45 0.06 -0.02' rgba='0 1 1 0' size='5e-3'/>
            </body>
			
            <body name = 'Toes_Right' pos = '0 0 0' >
            <geom type='mesh' name = 'Toes_Right' mesh='Toes_Right' mass='1' pos='0 0 0' euler='0 0 0' rgba='0.651 0.623 0.572 1'/>
            <joint name='Toes_Right:x' class='Toes_Right:x' axis='$Toes_Right:x:x$	$Toes_Right:x:y$	$Toes_Right:x:z$'  ref='0' pos='$Toes_Right:o:x$	$Toes_Right:o:y$	$Toes_Right:o:z$'/>
            <site name="T_Right" pos='$T_Right:x$	$T_Right:y$	$T_Right:z$' rgba='0 1 1 1' size='5e-3'/>
			<site name="EDL_Toes_Right" pos='$EDL_Toes_Right:x$	$EDL_Toes_Right:y$	$EDL_Toes_Right:z$' rgba='0 0 1 0' size='5e-3'/>
			<site name="FHL_Toes_Right" pos='$FHL_Toes_Right:x$	$FHL_Toes_Right:y$	$FHL_Toes_Right:z$' rgba='0 0 1 0' size='5e-3'/>
			<site name="EDL_ToesWrap_Right" pos='$EDL_ToesWrap_Right:x$	$EDL_ToesWrap_Right:y$	$EDL_ToesWrap_Right:z$' rgba='0 0 1 0' size='5e-3'/>
			<site name="FHL_ToesWrap_Right" pos='$FHL_ToesWrap_Right:x$	$FHL_ToesWrap_Right:y$	$FHL_ToesWrap_Right:z$' rgba='0 0 1 0' size='5e-3'/>
			
			<body name = 'Contact_Right'>
			<geom name = 'Contact_Right' pos='-0.525 0.055 -0.005' type = 'ellipsoid' size = '3.5e-2 2.2e-2 5e-4' rgba = '0 0.1 0.7 0' euler = '0 -20 10' density='0.'/>
			<site name="Contact_Tip_Right" pos='-0.525 0.055 -0.005' rgba='0 1 1 0' size='5e-3'/>
            </body>
			
			
			<geom type="cylinder" name='Foot_EDL_Right' density='0' fromto='-0.515 0.13 0.002  -0.495 0.03 0.002' size="0.005" rgba=".3 .9 .3 0."/>
	         <site name='slide5' pos='$EDL_ToesWrap_Right:x$	$EDL_ToesWrap_Right:y$	$EDL_ToesWrap_Right:z$'/>
			 <site name='slide6' pos='$FHL_ToesWrap_Right:x$	$FHL_ToesWrap_Right:y$	$FHL_ToesWrap_Right:z$'/>
            </body>
  				</body>
  				<!-- End foot
  				-->
  	</body>
  	<!-- End shin
  	-->
  </body>
  <!-- End leg
  -->

      <body name='GT_Holder_Left' pos='0 0 0' euler='0 0 0'>
        <site name="GT_Left" group='1' pos='$GT_Left:x$	$GT_Left:y$	$GT_Left:z$' rgba='1 1 0 1' size='5e-3'/>
      </body>

      <body name='Leg_Left' pos='0 0 0' euler='0 0 0'>

        <joint name='Hip_Left:x' class='Hip_Left:x' axis='$Hip_Left:x:x$	$Hip_Left:x:y$	$Hip_Left:x:z$' ref = '-90' pos='$Hip_Left:o:x$	$Hip_Left:o:y$	$Hip_Left:o:z$'/>
        <joint name='Hip_Left:y' class='Hip_Left:y' axis='$Hip_Left:y:x$	$Hip_Left:y:y$	$Hip_Left:y:z$' ref = '10' pos='$Hip_Left:o:x$	$Hip_Left:o:y$	$Hip_Left:o:z$'/>
        <joint name='Hip_Left:z' class='Hip_Left:z' axis='$Hip_Left:z:x$	$Hip_Left:z:y$	$Hip_Left:z:z$' ref = '0' pos='$Hip_Left:o:x$	$Hip_Left:o:y$	$Hip_Left:o:z$'/>

    	  <geom type='mesh' mesh='Femur_Left'  pos='0 0 0' euler='0 0 0' rgba='0.651 0.623 0.572 1'/>
		  
		  
			  <geom type="cylinder" name='Knee_FL' density='0' fromto='-0.18 -0.1 0.037  -0.2 0.0 0.037' size="0.015" rgba=".3 .9 .3 0."/>	  
	         <site name='slide7' pos='-0.19 -0.5 0.052'/>

        <site name="GMED_Femur_Left" pos='$GMED_Femur_Left:x$	$GMED_Femur_Left:y$	$GMED_Femur_Left:z$' rgba='0 0 1 0'/>

        <site name="IL_Femur_Left" pos='$IL_Femur_Left:x$	$IL_Femur_Left:y$	$IL_Femur_Left:z$' rgba='0 0 1 0'/>
        <site name="IL_Front_Left" pos='$IL_Front_Left:x$	$IL_Front_Left:y$	$IL_Front_Left:z$' rgba='0 0 1 0'/>

        <site name="VAS_Femur_Left" pos='$VAS_Femur_Left:x$	$VAS_Femur_Left:y$	$VAS_Femur_Left:z$' rgba='0 0 1 0'/>
        <site name="GAS_Femur_Left" pos='$GAS_Femur_Left:x$	$GAS_Femur_Left:y$	$GAS_Femur_Left:z$' rgba='0 0 1 0'/>
        <site name="GMAX_Femur_Left" pos='$GMAX_Femur_Left:x$	$GMAX_Femur_Left:y$	$GMAX_Femur_Left:z$' rgba='0 0 1 0'/>

        <site name="K_Left" pos='$K_Left:x$	$K_Left:y$	$K_Left:z$' rgba='1 0 0 0' size='5e-3'/>

    	  <body name='Shin_Left' pos='0 0 0' euler='0 0 0'>
		  
		  <geom type="cylinder" name='Knee_FL2' density='0' fromto='-0.205 -0.1 0.027  -0.225 0.0 0.027' size="0.012" rgba=".3 .9 .3 0."/>
	         <site name='slide8' pos='-0.215 -0.05 0.015'/>

            <geom type='mesh' mesh='Shin_Left'  pos='0 0 0' euler='0 0 0' rgba='0.651 0.623 0.572 1'/>

            <site name="VAS_Tibia_Left" pos='$VAS_Tibia_Left:x$	$VAS_Tibia_Left:y$	$VAS_Tibia_Left:z$' rgba='0 0 1 0'/>
            <site name="TA_Tibia_Left" pos='$TA_Tibia_Left:x$	$TA_Tibia_Left:y$	$TA_Tibia_Left:z$' rgba='0 0 1 0'/>
            <site name="SOL_Tibia_Left" pos='$SOL_Tibia_Left:x$	$SOL_Tibia_Left:y$	$SOL_Tibia_Left:z$' rgba='0 0 1 0'/>
            <site name="RF_Tibia_Left" pos='$RF_Tibia_Left:x$	$RF_Tibia_Left:y$	$RF_Tibia_Left:z$' rgba='0 0 1 0'/>
            <site name="BF_Tibia_Left" pos='$BF_Tibia_Left:x$	$BF_Tibia_Left:y$	$BF_Tibia_Left:z$' rgba='0 0 1 0'/>
			<site name="EDL_Tibia_Left" pos='$EDL_Tibia_Left:x$	$EDL_Tibia_Left:y$	$EDL_Tibia_Left:z$' rgba='0 0 1 0'/>
		    <site name="FHL_Shin_Left" pos='$FHL_Shin_Left:x$	$FHL_Shin_Left:y$	$FHL_Shin_Left:z$' rgba='0 0 1 0'/>

            <joint name='Knee_Left:x' class='Knee_Left:x' axis='$Knee_Left:x:x$	$Knee_Left:x:y$	$Knee_Left:x:z$'  ref='10' pos='$Knee_Left:o:x$	$Knee_Left:o:y$	$Knee_Left:o:z$'/>

    				<body name='Foot_Left' pos='0 0 0' >

              <geom type='mesh' mesh='Foot_Left'  pos='0 0 0' euler='0 0 0' rgba='0.651 0.623 0.572 1'/>

              <site name="M_Left" pos='$M_Left:x$	$M_Left:y$	$M_Left:z$' rgba='0.5 0.5 0.5 0' size='5e-3'/>
              <site name="MT_Left" pos='$MT_Left:x$	$MT_Left:y$	$MT_Left:z$' rgba='0 0 1 0' size='5e-3'/>
			  
			  <geom type="cylinder" name='Ankle_EDL_Left' density='0' fromto='-0.44 -0.13 -0.004  -0.42 -0.03 -0.004' size="0.008" rgba=".3 .9 .3 0."/>
	         <site name='slide9' pos='$EDL_Ankle_Left:x$	$EDL_Ankle_Left:y$	$EDL_Ankle_Left:z$'/>	
			 
			 <geom type="cylinder" name='Ankle_FHL_Left' density='0' fromto='-0.41 -0.13 -0.018  -0.39 -0.03 -0.018' size="0.01" rgba=".3 .9 .3 0."/>
	         <site name='slide10' pos='$FHL_Ankle_Left:x$	$FHL_Ankle_Left:y$	$FHL_Ankle_Left:z$'/>

              <site name="TA_Ankle_Left" pos='$TA_Ankle_Left:x$	$TA_Ankle_Left:y$	$TA_Ankle_Left:z$' rgba='0 0 1 0'/>
              <site name="SOL_Ankle_Left" pos='$SOL_Ankle_Left:x$	$SOL_Ankle_Left:y$	$SOL_Ankle_Left:z$' rgba='0 0 1 0'/>
              <site name="GAS_Ankle_Left" pos='$GAS_Ankle_Left:x$	$GAS_Ankle_Left:y$	$GAS_Ankle_Left:z$' rgba='0 0 1 0'/>
			  <site name="EDL_Ankle_Left" pos='$EDL_Ankle_Left:x$	$EDL_Ankle_Left:y$	$EDL_Ankle_Left:z$' rgba='0 0 1 0'/>
			  <site name="FHL_Ankle_Left" pos='$FHL_Ankle_Left:x$	$FHL_Ankle_Left:y$	$FHL_Ankle_Left:z$' rgba='0 0 1 0'/>
			  <site name="Site_EDL_Left" pos='$Site_EDL_Left:x$	$Site_EDL_Left:y$	$Site_EDL_Left:z$' rgba='0 0 1 0'/>
			  <site name="Site_FHL_Left" pos='$Site_FHL_Left:x$	$Site_FHL_Left:y$	$Site_FHL_Left:z$' rgba='0 0 1 0'/>

              <joint name='Ankle_Left:x' class='Ankle_Left:x' axis='$Ankle_Left:x:x$	$Ankle_Left:x:y$	$Ankle_Left:x:z$'  ref='45' pos='$Ankle_Left:o:x$	$Ankle_Left:o:y$	$Ankle_Left:o:z$'/>
              <joint name='Ankle_Left:y' class='Ankle_Left:y' axis='$Ankle_Left:y:x$	$Ankle_Left:y:y$	$Ankle_Left:y:z$'  ref='0'  pos='$Ankle_Left:o:x$	$Ankle_Left:o:y$	$Ankle_Left:o:z$'/>
			  
              <body name = 'Sole_Left'>
              <geom name = 'Sole_Left' pos='-0.45 -0.06 -0.02' type = 'ellipsoid' size = '5.5e-2 2.6e-2 5e-4' rgba = '1 0.5 0.5 0' euler = '0 20 -12' density='0.'/>
              <site name="Sole_Tip_Left" pos='-0.45 -0.06 -0.02' rgba='0 1 1 0' size='5e-3'/>
                </body>
				
              <body name = 'Toes_Left' pos = '0 0 0'>

              <site name="T_Left" pos='$T_Left:x$	$T_Left:y$	$T_Left:z$' rgba='0 1 1 0' size='5e-3'/>
			  <site name="EDL_Toes_Left" pos='$EDL_Toes_Left:x$	$EDL_Toes_Left:y$	$EDL_Toes_Left:z$' rgba='0 0 1 0' size='5e-3'/>			  
			  <site name="FHL_Toes_Left" pos='$FHL_Toes_Left:x$	$FHL_Toes_Left:y$	$FHL_Toes_Left:z$' rgba='0 0 1 0' size='5e-3'/>			  
			<site name="EDL_ToesWrap_Left" pos='$EDL_ToesWrap_Left:x$	$EDL_ToesWrap_Left:y$	$EDL_ToesWrap_Left:z$' rgba='0 0 1 0' size='5e-3'/>
			<site name="FHL_ToesWrap_Left" pos='$FHL_ToesWrap_Left:x$	$FHL_ToesWrap_Left:y$	$FHL_ToesWrap_Left:z$' rgba='0 0 1 0' size='5e-3'/>
              <geom type='mesh' name = 'Toes_Left' mesh='Toes_Left' mass='1' pos='0 0 0' euler='0 0 0' rgba='0.651 0.623 0.572 1'/>
              <joint name='Toes_Left:x' class='Toes_Left:x' axis='$Toes_Left:x:x$	$Toes_Left:x:y$	$Toes_Left:x:z$'  ref='0' pos='$Toes_Left:o:x$	$Toes_Left:o:y$	$Toes_Left:o:z$'/>
			  
			  <body name = 'Contact_Left'>
			<geom name = 'Contact_Left' pos='-0.525 -0.055 -0.005' type = 'ellipsoid' size = '3.5e-2 2.2e-2 5e-4' rgba = '0 0.1 0.7 0' euler = '0 -20 -10' density='0.'/>
			<site name="Contact_Tip_Left" pos='-0.525 -0.055 -0.005' rgba='0 1 1 0' size='5e-3'/>
            </body>		  
			  
			  <geom type="cylinder" name='Foot_EDL_Left' density='0' fromto='-0.515 -0.13 0.002  -0.495 -0.03 0.002' size="0.005" rgba=".3 .9 .3 0."/>
	         <site name='slide11' pos='$EDL_ToesWrap_Left:x$	$EDL_ToesWrap_Left:y$	$EDL_ToesWrap_Left:z$'/>
			 <site name='slide12' pos='$FHL_ToesWrap_Left:x$	$FHL_ToesWrap_Left:y$	$FHL_ToesWrap_Left:z$'/>

              </body>
    				</body>
    				<!-- End foot
    				-->
    	</body>
    	<!-- End shin
    	-->
    </body>
    <!-- End leg
    -->
     </body>
     <!--
     End Pelvis
   -->

    </body>
    <!-- End Lower bod
    -->

    <!--
    <body name = 'Treadmill' pos = '$World:xt$ $World:yt$ $World:zt$' quat = '$World:wq$ $World:xq$ $World:yq$ $World:zq$'>

      <geom name = 'Treadmill' type = 'box' size = '1 1 1e-12' pos = '$Floor:x$ $Floor:y$ $Floor:z$'/>
    -->
   <!-- <body name = 'Treadmill'>
      <geom name = 'Treadmill' type = 'box' size = '0.5 5 0.5' pos = '0 0 -0.96' rgba = '.2 .2 .2 1'/>
          <!-- -0.84 for corridor -->
              <!-- -0.96 for starbuck 

    </body>  --> <!--
    <body name = 'Enclosure'>
      <geom name = 'Enclosure' type = 'box' size = '1 5 1' pos = '0 0 -0.84' rgba = '1 0 0 .1' solref = '0.02 1'/>
    </body>
  -->
        <!--
    <body name = 'Posture Constraint' pos = '$World:xt$ $World:yt$ $World:zt$' quat = '$World:wq$ $World:xq$ $World:yq$ $World:zq$'>
      <geom name = 'Posture Constraint' type = 'sphere' size = '10e-3' rgba = '1 0 1 0.2' pos = '$T12:x$	$T12:y$	$T12:z$'/>
      <joint name = 'Posture:x' type = 'slide' axis = '1 0 0'/>
      <joint name = 'Posture:y' type = 'slide' axis = '0 1 0'/>
    </body>
      -->
	</worldbody>
	
	
    <equality>
      <distance geom1='T11' geom2 ='T12' distance = '0'/>
    </equality> 
	
	<equality>
      <distance geom1='T21' geom2 ='T22' distance = '0'/>
    </equality> 
	

  <contact>
    <exclude body1='Toes_Right'     body2='Treadmill'/>
      <exclude body1='Toes_Left'     body2='Treadmill'/>
        <exclude body1='Foot_Right'     body2='Treadmill'/>
          <exclude body1='Foot_Left'     body2='Treadmill'/> 
          
   <!-- <exclude body1='Treadmill'     body2='Enclosure'/>
        <exclude body1='Pelvis'     body2='Enclosure'/>
    <exclude body1='Leg_Right'     body2='Enclosure'/>
    <exclude body1='Leg_Left'     body2='Enclosure'/>
    <exclude body1='GT_Holder_Left'     body2='Enclosure'/>
    <exclude body1='GT_Holder_Right'     body2='Enclosure'/>
    <exclude body1='Shin_Right'     body2='Enclosure'/>
    <exclude body1='Shin_Left'     body2='Enclosure'/>
    <exclude body1='Foot_Right'     body2='Enclosure'/>
    <exclude body1='Foot_Left'     body2='Enclosure'/>
    <exclude body1='Toes_Right'     body2='Enclosure'/>
    <exclude body1='Toes_Left'     body2='Enclosure'/>
    <exclude body1='Sole_Right'     body2='Enclosure'/>
    <exclude body1='Sole_Left'     body2='Enclosure'/>-->
 
  </contact> 
  <tendon>
    <spatial name="IL_Left" stiffness="0" width="0.002" rgba=".95 .3 .3 $showTendons$" limited="false" range="0 0.33">
        <site site='IL_Pelvis_Left'/>
        <site site='IL_Femur_Left'/>
    </spatial>

    <spatial name="GMED_Left" stiffness="0" width="0.002" rgba=".95 .3 .3 $showTendons$" limited="false" range="0 0.33">
      <site site='GMED_Pelvis_Left'/>
      <site site='GMED_Femur_Left'/>
    </spatial>
	
	<spatial name="GMAX_Left" stiffness="0" width="0.002" rgba=".95 .3 .3 $showTendons$" limited="false" range="0 0.33">
      <site site='GMAX_Pelvis_Left'/>
      <site site='GMAX_Femur_Left'/>
    </spatial>
	
	<spatial name='BF_Left' stiffness="0" width="0.002" rgba=".95 .3 .3 $showTendons$" limited="false" range="0 0.33">
      <site site='BF_Pelvis_Left'/>
      <site site='BF_Tibia_Left'/>
    </spatial>
	
	<spatial name='RF_Left' stiffness="0" width="0.002" rgba=".95 .3 .3 $showTendons$" limited="false" range="0 0.33">
      <site site='RF_Pelvis_Left'/>
		<geom geom='Knee_FL' sidesite='slide7'/>
      <site site='RF_Tibia_Left'/>
    </spatial>

    <spatial name='VAS_Left' stiffness="0" width="0.002" rgba=".95 .3 .3 $showTendons$" limited="false" range="0 0.33">
      <site site='VAS_Femur_Left'/>
		<geom geom='Knee_FL' sidesite='slide7'/>
      <site site='VAS_Tibia_Left'/>
    </spatial>
	
    <spatial name='GAS_Left' stiffness="0" width="0.002" rgba=".95 .3 .3 $showTendons$" limited="false" range="0 0.33">
      <site site='GAS_Femur_Left'/>
		<geom geom='Knee_FL2' sidesite='slide8'/>
      <site site='GAS_Ankle_Left'/>
    </spatial>

    <spatial name='SOL_Left' stiffness="0" width="0.002" rgba=".95 .3 .3 $showTendons$" limited="false" range="0 0.33">
      <site site='SOL_Tibia_Left'/>
      <site site='SOL_Ankle_Left'/>
    </spatial>
	
	<spatial name='TA_Left' stiffness="0" width="0.002" rgba=".95 .3 .3 $showTendons$" limited="false" range="0 0.33">
      <site site='TA_Tibia_Left'/>
      <site site='TA_Ankle_Left'/>
    </spatial>
	
	<spatial name='EDL_Left' stiffness="0" width="0.002" rgba=".95 .3 .3 $showTendons$" limited="false" range="0 0.33">
      <site site='EDL_Tibia_Left'/>
	  <geom geom='Ankle_EDL_Left' sidesite='slide9'/>
	  <site site='Site_EDL_Left'/>
	  <geom geom='Foot_EDL_Left' sidesite='slide11'/>
		<site site='EDL_Toes_Left'/>
    </spatial>
	
	<spatial name='FHL_Left' stiffness="0" width="0.002" rgba=".95 .3 .3 $showTendons$" limited="false" range="0 0.33">
      <site site='FHL_Shin_Left'/>
	  <geom geom='Ankle_FHL_Left' sidesite='slide10'/>
	  <site site='Site_FHL_Left'/>
	  <geom geom='Foot_EDL_Left' sidesite='slide12'/>
		<site site='FHL_Toes_Left'/>
    </spatial>
	
	
      <spatial name="IL_Right" stiffness="0" width="0.002" rgba=".95 .3 .3 $showTendons$" limited="false" range="0 0.33">
          <site site='IL_Pelvis_Right'/>
          <site site='IL_Femur_Right'/> 
      </spatial>

      <spatial name="GMED_Right" stiffness="0" width="0.002" rgba=".95 .3 .3 $showTendons$" limited="false" range="0 0.33">
        <site site='GMED_Pelvis_Right'/>
        <site site='GMED_Femur_Right'/>
      </spatial>	  
	  
	  <spatial name="GMAX_Right" stiffness="0" width="0.002" rgba=".95 .3 .3 $showTendons$" limited="false" range="0 0.33">
      <site site='GMAX_Pelvis_Right'/>
      <site site='GMAX_Femur_Right'/>
    </spatial>
	  
      <spatial name='BF_Right' stiffness="0" width="0.002" rgba=".95 .3 .3 $showTendons$" limited="false" range="0 0.33">
        <site site='BF_Pelvis_Right'/>
        <site site='BF_Tibia_Right'/>
      </spatial>
	  
	  <spatial name='RF_Right' stiffness="0" width="0.002" rgba=".95 .3 .3 $showTendons$" limited="false" range="0 0.33">
        <site site='RF_Pelvis_Right'/>
		<geom geom='Knee_FR' sidesite='slide1'/>
        <site site='RF_Tibia_Right'/>
      </spatial>

      <spatial name='VAS_Right' stiffness="0" width="0.002" rgba=".95 .3 .3 $showTendons$" limited="false" range="0 0.33">
        <site site='VAS_Femur_Right'/>
		<geom geom='Knee_FR' sidesite='slide1'/> 
        <site site='VAS_Tibia_Right'/>
      </spatial>
	  
	  <spatial name='GAS_Right' stiffness="0" width="0.002" rgba=".95 .3 .3 $showTendons$" limited="false" range="0 0.33">
        <site site='GAS_Femur_Right'/>
		<geom geom='Knee_FR2' sidesite='slide2'/>
        <site site='GAS_Ankle_Right'/>
      </spatial>
	  
	  <spatial name='SOL_Right' stiffness="0" width="0.002" rgba=".95 .3 .3 $showTendons$" limited="false" range="0 0.33">
        <site site='SOL_Tibia_Right'/>
        <site site='SOL_Ankle_Right'/>
      </spatial>

      <spatial name='TA_Right' stiffness="0" width="0.002" rgba=".95 .3 .3 $showTendons$" limited="false" range="0 0.33">
        <site site='TA_Tibia_Right'/>
        <site site='TA_Ankle_Right'/>
      </spatial>
	  
	<spatial name='EDL_Right' stiffness="0" width="0.002" rgba=".95 .3 .3 $showTendons$" limited="false" range="0 0.33">
      <site site='EDL_Tibia_Right'/>
	  <geom geom='Ankle_EDL_Right' sidesite='slide3'/>
	  <site site='Site_EDL_Right'/>
	  <geom geom='Foot_EDL_Right' sidesite='slide5'/>
		<site site='EDL_Toes_Right'/>
    </spatial>
	
		<spatial name='FHL_Right' stiffness="0" width="0.002" rgba=".95 .3 .3 $showTendons$" limited="false" range="0 0.33">
      <site site='FHL_Shin_Right'/>
	  <geom geom='Ankle_FHL_Right' sidesite='slide4'/>
	  <site site='Site_FHL_Right'/>
	  <geom geom='Foot_EDL_Right' sidesite='slide6'/>
		<site site='FHL_Toes_Right'/>
    </spatial>
	
</tendon>


<actuator>
  
  <general name='IL_Left'    gear='1' tendon='IL_Left'    ctrllimited='true' ctrlrange='-1 0' gainprm='642'  biastype="affine" biasprm='0 0 -91'/>
  <general name='GMED_Left'  gear='1' tendon='GMED_Left'  ctrllimited='true' ctrlrange='-1 0' gainprm='738'  biastype="affine" biasprm='0 0 -91'/>
  <general name='GMAX_Left'  gear='1' tendon='GMAX_Left'  ctrllimited='true' ctrlrange='-1 0' gainprm='738'  biastype="affine" biasprm='0 0 -91'/>
  <general name='BF_Left'    gear='1' tendon='BF_Left'    ctrllimited='true' ctrlrange='-1 0' gainprm='804'  biastype="affine" biasprm='0 0 -91'/>
  <general name='RF_Left'    gear='1' tendon='RF_Left'    ctrllimited='true' ctrlrange='-1 0' gainprm='720'  biastype="affine" biasprm='0 0 -100'/>
  <general name='VAS_Left'   gear='1' tendon='VAS_Left'   ctrllimited='true' ctrlrange='-1 0' gainprm='2514' biastype="affine" biasprm='0 0 -100'/> 
  <general name='GAS_Left'   gear='1' tendon='GAS_Left'   ctrllimited='true' ctrlrange='-1 0' gainprm='720'  biastype="affine" biasprm='0 0 -91'/>
  <general name='SOL_Left'   gear='1' tendon='SOL_Left'   ctrllimited='true' ctrlrange='-1 0' gainprm='822'  biastype="affine" biasprm='0 0 -66'/>
  <general name='TA_Left'    gear='1' tendon='TA_Left'    ctrllimited='true' ctrlrange='-1 0' gainprm='390'  biastype="affine" biasprm='0 0 -66'/>
  <general name='EDL_Left'   gear='1' tendon='EDL_Left'   ctrllimited='true' ctrlrange='-1 0' gainprm='390'  biastype="affine" biasprm='0 0 -66'/>
  <general name='FHL_Left'   gear='1' tendon='FHL_Left'   ctrllimited='true' ctrlrange='-1 0' gainprm='390'  biastype="affine" biasprm='0 0 -66'/>
  
  <general name='IL_Right'    gear='1' tendon='IL_Right'    ctrllimited='true' ctrlrange='-1 0' gainprm='642'  biastype="affine" biasprm='0 0 -91'/>
  <general name='GMED_Right'  gear='1' tendon='GMED_Right'  ctrllimited='true' ctrlrange='-1 0' gainprm='738'  biastype="affine" biasprm='0 0 -91'/>
  <general name='GMAX_Right'  gear='1' tendon='GMAX_Right'  ctrllimited='true' ctrlrange='-1 0' gainprm='738'  biastype="affine" biasprm='0 0 -91'/>
  <general name='BF_Right'    gear='1' tendon='BF_Right'    ctrllimited='true' ctrlrange='-1 0' gainprm='804'  biastype="affine" biasprm='0 0 -91'/>
  <general name='RF_Right'    gear='1' tendon='RF_Right'    ctrllimited='true' ctrlrange='-1 0' gainprm='720'  biastype="affine" biasprm='0 0 -100'/>
  <general name='VAS_Right'   gear='1' tendon='VAS_Right'   ctrllimited='true' ctrlrange='-1 0' gainprm='2514' biastype="affine" biasprm='0 0 -100'/> 
  <general name='GAS_Right'   gear='1' tendon='GAS_Right'   ctrllimited='true' ctrlrange='-1 0' gainprm='720'  biastype="affine" biasprm='0 0 -91'/>
  <general name='SOL_Right'   gear='1' tendon='SOL_Right'   ctrllimited='true' ctrlrange='-1 0' gainprm='822'  biastype="affine" biasprm='0 0 -66'/>
  <general name='TA_Right'    gear='1' tendon='TA_Right'    ctrllimited='true' ctrlrange='-1 0' gainprm='390'  biastype="affine" biasprm='0 0 -66'/>
  <general name='EDL_Right'   gear='1' tendon='EDL_Right'   ctrllimited='true' ctrlrange='-1 0' gainprm='390'  biastype="affine" biasprm='0 0 -66'/>
  <general name='FHL_Right'   gear='1' tendon='FHL_Right'   ctrllimited='true' ctrlrange='-1 0' gainprm='390'  biastype="affine" biasprm='0 0 -66'/>
  
</actuator>


<keyframe>
  <!-- reference for Ia calculation -->
    <key time="0" qpos="0 0 0   1 0 0 0   0 0 0   1.3 -0.6 0 -0.52   0 0 0   -1.3 0.6 0 0.52" />
      <!-- reference for Ia calculation -->
    <key time="0" qpos="0 0 0 1 0 0 0 0 0 0 0 0 0 0  0   -0.08 0.05 -1.5 0.2 0.1 0.52" />
    <key time = '0' qpos = '0.05 0.07 -0.05 0.57 0.45 -0.53 0.43 -0.6 0.08 -0.05 1.55 -1.51 0.11 30 0.6 -0.08 0.05 -1.55 1.51 -0.11 -30'/>
</keyframe>

</mujoco>
