<mujoco model="Murdoc">

    <compiler inertiafromgeom='true' angle='degree'/>
    <option gravity='0 0 0'/>
    <asset>
		<!-- Sets sky rendering
		-->
        <texture type="skybox" builtin="gradient" width="100" height="100" rgb1="0 0 0"
            rgb2="0 0 0"/>
		<!-- Not clear to me where this is used yet
		-->
        <texture name="texgeom" type="cube" builtin="flat" mark="cross" width="127" height="1278"
            rgb1="0.1 0.8 0.1" rgb2="0.8 0.6 0.4" markrgb="1 1 1" random="0.01"/>
		<!-- Sets floor rendering
		-->
        <texture name="texplane" type="2d" builtin="checker" rgb1=".2 .3 .4" rgb2=".1 0.15 0.2"
            width="1000" height="1000"/>
        <texture name='bone_texture' type="cube" file="$Murdoc_Dir$/Bone.png"/>
		<!-- Create materials based on textures above
		-->
        <material name='MatPlane' reflectance='0.5' texture="texplane"/>
        <material name='geom' texture="texgeom" texuniform="true"/>
        <material name='bone' texture='bone_texture' reflectance='0' texuniform='true' specular='0' shininess='0'/>

        <mesh file="$Murdoc_Dir$/Pelvis.stl" scale='1e-3 1e-3 1e-3' />
        <mesh file="$Murdoc_Dir$/Femur_Left.stl" scale='1e-3 1e-3 1e-3' />
        <mesh file="$Murdoc_Dir$/Femur_Right.stl" scale='1e-3 1e-3 1e-3' />
        <mesh file="$Murdoc_Dir$/Shin_Left.stl" scale='1e-3 1e-3 1e-3' />
        <mesh file="$Murdoc_Dir$/Shin_Right.stl" scale='1e-3 1e-3 1e-3' />
        <mesh file="$Murdoc_Dir$/Foot_Left.stl" scale='1e-3 1e-3 1e-3' />
        <mesh file="$Murdoc_Dir$/Foot_Right.stl" scale='1e-3 1e-3 1e-3' />

    </asset>

	<default>
    <site size='
      0.5e-3 0.5e-3 0.5e-3' rgba='1 0 0 0'/>

    <default class='Hip:x'>
      <joint type='hinge' axis='0 1 0' ref='0' range='-60 90' limited='true' armature='0.0001' stiffness='0' springref='0'/>
		</default>
		<default class='Hip:y'>
            <joint type='hinge' axis='0 1 0' range='-15 15' damping='5' limited='true' stiffness='0' armature='0.0080' />
		</default>
		<default class='Hip:z'>
            <joint type='hinge' axis='0 0 1' range='-15 15' damping='5' limited='true' stiffness='0' armature='0.0080' />
		</default>
		<default class = 'Knee:x'>
			<joint type='hinge' axis='1 0 0' range='-90  70' limited='true'  armature='0.0006'  stiffness='0' springref='0'/>
		</default>
		<default class = 'Knee:y'>
			<joint type='hinge' axis='1 0 0' range='-120 40' limited='true'  armature='0.0006'  stiffness='0' springref='0'/>
		</default>
		<default class = 'Ankle:x'>
			<joint type='hinge' axis='1 0 0' pos='0 0 0' range='-60 120' limited='true'  armature='0.0006' stiffness='0' springref='0'/>
		</default>
		<default class = 'Ankle:y'>
			<joint type='hinge' axis='0 1 0' pos='0 0 0' range='-30 30' limited='true'  armature='0.0006' stiffness='0' springref='0'/>
		</default>
	</default>

	<worldbody>
    <light directional='true' diffuse='1 1 1' specular='0 0 0' pos='0 0 40.5' dir='0 1 0'/>

    <body name='Lower_Body' pos='0 0 0' euler='0 0 0'>

    <body name='Pelvis' pos='0 0 0' euler='0 0 0'>
    <joint name='World:xt' type='slide' axis='1 0 0' pos='0 0 0$' ref='$Pelvis_Origin:x$' limited='false' />
    <joint name='World:yt' type='slide' axis='0 1 0' pos='0 0 0$' ref='$Pelvis_Origin:y$' limited='false' />
    <joint name='World:zt' type='slide' axis='0 0 1' pos='0 0 0$' ref='$Pelvis_Origin:z$' limited='false' />

    <joint name='World:x' type='hinge' axis='1 0 0' pos='$Pelvis_Origin:x$	$Pelvis_Origin:y$	$Pelvis_Origin:z$' ref='185' limited='false'  />
    <joint name='World:y' type='hinge' axis='0 1 0' pos='$Pelvis_Origin:x$	$Pelvis_Origin:y$	$Pelvis_Origin:z$' ref='10' limited='false'  />
    <joint name='World:z' type='hinge' axis='0 0 1' pos='$Pelvis_Origin:x$	$Pelvis_Origin:y$	$Pelvis_Origin:z$' ref='0' limited='false'  />

     <site name="BF_Pelvis_Left" pos='$BF_Pelvis_Left:x$	$BF_Pelvis_Left:y$	$BF_Pelvis_Left:z$' rgba='1 0 0 0'/>
     <site name="RF_Pelvis_Left" pos='$RF_Pelvis_Left:x$	$RF_Pelvis_Left:y$	$RF_Pelvis_Left:z$' rgba='1 0 0 0'/>
     <site name="GMED_Pelvis_Left" pos='$GMED_Pelvis_Left:x$	$GMED_Pelvis_Left:y$	$GMED_Pelvis_Left:z$' rgba='1 0 0 0'/>
     <site name="IL_Pelvis_Left" pos='$IL_Pelvis_Left:x$	$IL_Pelvis_Left:y$	$IL_Pelvis_Left:z$' rgba='1 0 0 0'/>

     <site name="GMED_Pelvis_Right" pos='$GMED_Pelvis_Right:x$	$GMED_Pelvis_Right:y$	$GMED_Pelvis_Right:z$' rgba='0 0 1 0'/>
     <site name="IL_Pelvis_Right" pos='$IL_Pelvis_Right:x$	$IL_Pelvis_Right:y$	$IL_Pelvis_Right:z$' rgba='0 0 1 0'/>
     <site name="RF_Pelvis_Right" pos='$RF_Pelvis_Right:x$	$RF_Pelvis_Right:y$	$RF_Pelvis_Right:z$' rgba='0 0 1 0'/>
     <site name="BF_Pelvis_Right" pos='$BF_Pelvis_Right:x$	$BF_Pelvis_Right:y$	$BF_Pelvis_Right:z$' rgba='0 0 1 0'/>

     <site name="C_Right" group='1' pos='$C_Right:x$	$C_Right:y$	$C_Right:z$' rgba='1 1 1 1' size='5e-3'/>
     <site name="C_Left" group='1' pos='$C_Left:x$	$C_Left:y$	$C_Left:z$' rgba='1 1 1 1' size='5e-3'/>

     <geom type='mesh' mesh='Pelvis' density='1' pos='0 0 0' euler='0 0 0' rgba='0.651 0.623 0.572 1'/>

      <body name='GT_Holder_Right' pos='0 0 0' euler='0 0 0'>
        <site name="GT_Right" group='1' pos='$GT_Right:x$	$GT_Right:y$	$GT_Right:z$' rgba='1 1 0 1' size='5e-3'/>
      </body>

    <body name='Leg_Right' pos='0 0 0' euler='0 0 0'>

      <joint name='Hip_Right:x' class='Hip:x' axis='$Hip_Right:x:x$	$Hip_Right:x:y$	$Hip_Right:x:z$' ref = '0' pos='$Hip_Right:o:x$	$Hip_Right:o:y$	$Hip_Right:o:z$'/>
      <joint name='Hip_Right:y' class='Hip:y' axis='$Hip_Right:y:x$	$Hip_Right:y:y$	$Hip_Right:y:z$' ref = '-10' pos='$Hip_Right:o:x$	$Hip_Right:o:y$	$Hip_Right:o:z$'/>
      <joint name='Hip_Right:z' class='Hip:z' axis='$Hip_Right:z:x$	$Hip_Right:z:y$	$Hip_Right:z:z$' ref = '0' pos='$Hip_Right:o:x$	$Hip_Right:o:y$	$Hip_Right:o:z$'/>

  	  <geom type='mesh' mesh='Femur_Right' density='1' pos='0 0 0' euler='0 0 0' rgba='0.651 0.623 0.572 1'/>

      <site name="GMED_Femur_Right" pos='$GMED_Femur_Right:x$	$GMED_Femur_Right:y$	$GMED_Femur_Right:z$' rgba='0 0 1 0'/>

      <site name="IL_Femur_Right" pos='$IL_Femur_Right:x$	$IL_Femur_Right:y$	$IL_Femur_Right:z$' rgba='0 0 1 0'/>
      <site name="IL_Front_Right" pos='$IL_Front_Right:x$	$IL_Front_Right:y$	$IL_Front_Right:z$' rgba='0 0 1 0'/>

      <site name="VAS_Femur_Right" pos='$VAS_Femur_Right:x$	$VAS_Femur_Right:y$	$VAS_Femur_Right:z$' rgba='0 0 1 0'/>
      <site name="GAS_Femur_Right" pos='$GAS_Femur_Right:x$	$GAS_Femur_Right:y$	$GAS_Femur_Right:z$' rgba='0 0 1 0'/>

      <site name="K_Right" pos='$K_Right:x$	$K_Right:y$	$K_Right:z$' rgba='1 0 0 1' size='5e-3'/>

  	  <body name='Shin_Right' pos='0 0 0' euler='0 0 0'>

          <geom type='mesh' mesh='Shin_Right' density='1' pos='0 0 0' euler='0 0 0' rgba='0.651 0.623 0.572 1'/>

          <site name="VAS_Tibia_Right" pos='$VAS_Tibia_Right:x$	$VAS_Tibia_Right:y$	$VAS_Tibia_Right:z$' rgba='0 0 1 0'/>
          <site name="TA_Tibia_Right" pos='$TA_Tibia_Right:x$	$TA_Tibia_Right:y$	$TA_Tibia_Right:z$' rgba='0 0 1 0'/>
          <site name="SOL_Tibia_Right" pos='$SOL_Tibia_Right:x$	$SOL_Tibia_Right:y$	$SOL_Tibia_Right:z$' rgba='0 0 1 0'/>
          <site name="RF_Tibia_Right" pos='$RF_Tibia_Right:x$	$RF_Tibia_Right:y$	$RF_Tibia_Right:z$' rgba='0 0 1 0'/>
          <site name="BF_Tibia_Right" pos='$BF_Tibia_Right:x$	$BF_Tibia_Right:y$	$BF_Tibia_Right:z$' rgba='0 0 1 0'/>

          <joint name='Knee_Right:x' class='Knee:x' axis='$Knee_Right:x:x$	$Knee_Right:x:y$	$Knee_Right:x:z$' ref='-60' pos='$Knee_Right:o:x$	$Knee_Right:o:y$	$Knee_Right:o:z$'/>

  				<body name='Foot_Right' pos='0 0 0' >

            <geom type='mesh' mesh='Foot_Right' density='1' pos='0 0 0' euler='0 0 0' rgba='0.651 0.623 0.572 1'/>

            <site name="M_Right" pos='$M_Right:x$	$M_Right:y$	$M_Right:z$' rgba='0.5 0.5 0.5 1' size='5e-3'/>
            <site name="MT_Right" pos='$MT_Right:x$	$MT_Right:y$	$MT_Right:z$' rgba='0 0 1 1' size='5e-3'/>
            <site name="T_Right" pos='$T_Right:x$	$T_Right:y$	$T_Right:z$' rgba='0 1 1 1' size='5e-3'/>

            <site name="TA_Ankle_Right" pos='$TA_Ankle_Right:x$	$TA_Ankle_Right:y$	$TA_Ankle_Right:z$' rgba='0 0 1 0'/>
            <site name="SOL_Ankle_Right" pos='$SOL_Ankle_Right:x$	$SOL_Ankle_Right:y$	$SOL_Ankle_Right:z$' rgba='0 0 1 0'/>
            <site name="GAS_Ankle_Right" pos='$GAS_Ankle_Right:x$	$GAS_Ankle_Right:y$	$GAS_Ankle_Right:z$' rgba='0 0 1 0'/>

            <joint name='Ankle_Right:x' class='Ankle:x' axis='$Ankle_Right:x:x$	$Ankle_Right:x:y$	$Ankle_Right:x:z$'  ref='60' pos='$Ankle_Right:o:x$	$Ankle_Right:o:y$	$Ankle_Right:o:z$'/>
            <joint name='Ankle_Right:y' class='Ankle:y' axis='$Ankle_Right:y:x$	$Ankle_Right:y:y$	$Ankle_Right:y:z$'  pos='$Ankle_Right:o:x$	$Ankle_Right:o:y$	$Ankle_Right:o:z$'/>

  				</body>
  				<!-- End foot
  				-->
  	</body>
  	<!-- End shin
  	-->
  </body>
  <!-- End leg
  -->

      <body name='GT_Holder_Left' pos='0 0 0' euler='0 0 0'>
        <site name="GT_Left" group='1' pos='$GT_Left:x$	$GT_Left:y$	$GT_Left:z$' rgba='1 1 0 1' size='5e-3'/>
      </body>

      <body name='Leg_Left' pos='0 0 0' euler='0 0 0'>

        <joint name='Hip_Left:x' class='Hip:x' axis='$Hip_Left:x:x$	$Hip_Left:x:y$	$Hip_Left:x:z$' ref = '10' pos='$Hip_Left:o:x$	$Hip_Left:o:y$	$Hip_Left:o:z$'/>
        <joint name='Hip_Left:y' class='Hip:y' axis='$Hip_Left:y:x$	$Hip_Left:y:y$	$Hip_Left:y:z$' ref = '10' pos='$Hip_Left:o:x$	$Hip_Left:o:y$	$Hip_Left:o:z$'/>
        <joint name='Hip_Left:z' class='Hip:z' axis='$Hip_Left:z:x$	$Hip_Left:z:y$	$Hip_Left:z:z$' ref = '30' pos='$Hip_Left:o:x$	$Hip_Left:o:y$	$Hip_Left:o:z$'/>

    	  <geom type='mesh' mesh='Femur_Left' density='1' pos='0 0 0' euler='0 0 0' rgba='0.651 0.623 0.572 1'/>

        <site name="GMED_Femur_Left" pos='$GMED_Femur_Left:x$	$GMED_Femur_Left:y$	$GMED_Femur_Left:z$' rgba='0 0 1 0'/>

        <site name="IL_Femur_Left" pos='$IL_Femur_Left:x$	$IL_Femur_Left:y$	$IL_Femur_Left:z$' rgba='0 0 1 0'/>
        <site name="IL_Front_Left" pos='$IL_Front_Left:x$	$IL_Front_Left:y$	$IL_Front_Left:z$' rgba='0 0 1 0'/>

        <site name="VAS_Femur_Left" pos='$VAS_Femur_Left:x$	$VAS_Femur_Left:y$	$VAS_Femur_Left:z$' rgba='0 0 1 0'/>
        <site name="GAS_Femur_Left" pos='$GAS_Femur_Left:x$	$GAS_Femur_Left:y$	$GAS_Femur_Left:z$' rgba='0 0 1 0'/>

        <site name="K_Left" pos='$K_Left:x$	$K_Left:y$	$K_Left:z$' rgba='1 0 0 1' size='5e-3'/>

    	  <body name='Shin_Left' pos='0 0 0' euler='0 0 0'>

            <geom type='mesh' mesh='Shin_Left' density='1' pos='0 0 0' euler='0 0 0' rgba='0.651 0.623 0.572 1'/>

            <site name="VAS_Tibia_Left" pos='$VAS_Tibia_Left:x$	$VAS_Tibia_Left:y$	$VAS_Tibia_Left:z$' rgba='0 0 1 0'/>
            <site name="TA_Tibia_Left" pos='$TA_Tibia_Left:x$	$TA_Tibia_Left:y$	$TA_Tibia_Left:z$' rgba='0 0 1 0'/>
            <site name="SOL_Tibia_Left" pos='$SOL_Tibia_Left:x$	$SOL_Tibia_Left:y$	$SOL_Tibia_Left:z$' rgba='0 0 1 0'/>
            <site name="RF_Tibia_Left" pos='$RF_Tibia_Left:x$	$RF_Tibia_Left:y$	$RF_Tibia_Left:z$' rgba='0 0 1 0'/>
            <site name="BF_Tibia_Left" pos='$BF_Tibia_Left:x$	$BF_Tibia_Left:y$	$BF_Tibia_Left:z$' rgba='0 0 1 0'/>

            <joint name='Knee_Left:x' class='Knee:x' axis='$Knee_Left:x:x$	$Knee_Left:x:y$	$Knee_Left:x:z$'  ref='-60' pos='$Knee_Left:o:x$	$Knee_Left:o:y$	$Knee_Left:o:z$'/>

    				<body name='Foot_Left' pos='0 0 0' >

              <geom type='mesh' mesh='Foot_Left' density='1' pos='0 0 0' euler='0 0 0' rgba='0.651 0.623 0.572 1'/>

              <site name="M_Left" pos='$M_Left:x$	$M_Left:y$	$M_Left:z$' rgba='0.5 0.5 0.5 1' size='5e-3'/>
              <site name="MT_Left" pos='$MT_Left:x$	$MT_Left:y$	$MT_Left:z$' rgba='0 0 1 1' size='5e-3'/>
              <site name="T_Left" pos='$T_Left:x$	$T_Left:y$	$T_Left:z$' rgba='0 1 1 1' size='5e-3'/>

              <site name="TA_Ankle_Left" pos='$TA_Ankle_Left:x$	$TA_Ankle_Left:y$	$TA_Ankle_Left:z$' rgba='0 0 1 0'/>
              <site name="SOL_Ankle_Left" pos='$SOL_Ankle_Left:x$	$SOL_Ankle_Left:y$	$SOL_Ankle_Left:z$' rgba='0 0 1 0'/>
              <site name="GAS_Ankle_Left" pos='$GAS_Ankle_Left:x$	$GAS_Ankle_Left:y$	$GAS_Ankle_Left:z$' rgba='0 0 1 0'/>

              <joint name='Ankle_Left:x' class='Ankle:x' axis='$Ankle_Left:x:x$	$Ankle_Left:x:y$	$Ankle_Left:x:z$'  ref='60' pos='$Ankle_Left:o:x$	$Ankle_Left:o:y$	$Ankle_Left:o:z$'/>
              <joint name='Ankle_Left:y' class='Ankle:y' axis='$Ankle_Left:y:x$	$Ankle_Left:y:y$	$Ankle_Left:y:z$'  ref='0' pos='$Ankle_Left:o:x$	$Ankle_Left:o:y$	$Ankle_Left:o:z$'/>
    				</body>
    				<!-- End foot
    				-->
    	</body>
    	<!-- End shin
    	-->
    </body>
    <!-- End leg
    -->
     </body>
     <!--
     End Pelvis
   -->

    </body>
    <!-- End Lower bod
    -->
	</worldbody>

  <tendon>
    <spatial name="IL_Left" stiffness="0" width="0.002" rgba=".95 .3 .3 0" limited="false" range="0 0.33">
        <site site='IL_Pelvis_Left'/>
        <site site='IL_Femur_Left'/>
    </spatial>

    <spatial name="GMED_Left" stiffness="0" width="0.002" rgba=".95 .3 .3 0" limited="false" range="0 0.33">
      <site site='GMED_Pelvis_Left'/>
      <site site='GMED_Femur_Left'/>
    </spatial>

    <spatial name='VAS_Left' stiffness="0" width="0.002" rgba=".95 .3 .3 0" limited="false" range="0 0.33">
      <site site='VAS_Femur_Left'/>
      <site site='VAS_Tibia_Left'/>
    </spatial>

    <spatial name='TA_Left' stiffness="0" width="0.002" rgba=".95 .3 .3 0" limited="false" range="0 0.33">
      <site site='TA_Tibia_Left'/>
      <site site='TA_Ankle_Left'/>
    </spatial>

    <spatial name='SOL_Left' stiffness="0" width="0.002" rgba=".95 .3 .3 0" limited="false" range="0 0.33">
      <site site='SOL_Tibia_Left'/>
      <site site='SOL_Ankle_Left'/>
    </spatial>

    <spatial name='RF_Left' stiffness="0" width="0.002" rgba=".95 .3 .3 0" limited="false" range="0 0.33">
      <site site='RF_Pelvis_Left'/>
      <site site='RF_Tibia_Left'/>
    </spatial>

    <spatial name='BF_Left' stiffness="0" width="0.002" rgba=".95 .3 .3 0" limited="false" range="0 0.33">
      <site site='BF_Pelvis_Left'/>
      <site site='BF_Tibia_Left'/>
    </spatial>

    <spatial name='GAS_Left' stiffness="0" width="0.002" rgba=".95 .3 .3 0" limited="false" range="0 0.33">
      <site site='GAS_Femur_Left'/>
      <site site='GAS_Ankle_Left'/>
    </spatial>
      <spatial name="IL_Right" stiffness="0" width="0.002" rgba=".95 .3 .3 0" limited="false" range="0 0.33">
          <site site='IL_Pelvis_Right'/>
          <site site='IL_Femur_Right'/>
      </spatial>

      <spatial name="GMED_Right" stiffness="0" width="0.002" rgba=".95 .3 .3 0" limited="false" range="0 0.33">
        <site site='GMED_Pelvis_Right'/>
        <site site='GMED_Femur_Right'/>
      </spatial>

      <spatial name='VAS_Right' stiffness="0" width="0.002" rgba=".95 .3 .3 0" limited="false" range="0 0.33">
        <site site='VAS_Femur_Right'/>
        <site site='VAS_Tibia_Right'/>
      </spatial>

      <spatial name='TA_Right' stiffness="0" width="0.002" rgba=".95 .3 .3 0" limited="false" range="0 0.33">
        <site site='TA_Tibia_Right'/>
        <site site='TA_Ankle_Right'/>
      </spatial>

      <spatial name='SOL_Right' stiffness="0" width="0.002" rgba=".95 .3 .3 0" limited="false" range="0 0.33">
        <site site='SOL_Tibia_Right'/>
        <site site='SOL_Ankle_Right'/>
      </spatial>

      <spatial name='RF_Right' stiffness="0" width="0.002" rgba=".95 .3 .3 0" limited="false" range="0 0.33">
        <site site='RF_Pelvis_Right'/>
        <site site='RF_Tibia_Right'/>
      </spatial>

      <spatial name='BF_Right' stiffness="0" width="0.002" rgba=".95 .3 .3 0" limited="false" range="0 0.33">
        <site site='BF_Pelvis_Right'/>
        <site site='BF_Tibia_Right'/>
      </spatial>

      <spatial name='GAS_Right' stiffness="0" width="0.002" rgba=".95 .3 .3 0" limited="false" range="0 0.33">
        <site site='GAS_Femur_Right'/>
        <site site='GAS_Ankle_Right'/>
      </spatial>
</tendon>

<actuator>
  <general name='IL_Right'   gear='1' tendon='IL_Right'   ctrllimited='true' ctrlrange='-1 1' gainprm='642' biastype="affine" biasprm='0 0 -91'/>
  <general name='IL_Left'   gear='1' tendon='IL_Left'   ctrllimited='true' ctrlrange='-1 1' gainprm='642' biastype="affine" biasprm='0 0 -91'/>

  <general name='GMED_Right' gear='1' tendon='GMED_Right' ctrllimited='true' ctrlrange='-1 1' gainprm='738' biastype="affine" biasprm='0 0 -91'/>
  <general name='GMED_Left' gear='1' tendon='GMED_Left' ctrllimited='true' ctrlrange='-1 1' gainprm='738' biastype="affine" biasprm='0 0 -91'/>

  <general name='VAS_Right'  gear='1' tendon='VAS_Right'  ctrllimited='true' ctrlrange='-1 1' gainprm='2514' biastype="affine" biasprm='0 0 -100'/>
  <general name='VAS_Left'  gear='1' tendon='VAS_Left'  ctrllimited='true' ctrlrange='-1 1' gainprm='2514' biastype="affine" biasprm='0 0 -100'/>

  <general name='TA_Right'   gear='1' tendon='TA_Right'   ctrllimited='true' ctrlrange='-1 1' gainprm='390' biastype="affine" biasprm='0 0 -66'/>
  <general name='TA_Left'   gear='1' tendon='TA_Left'   ctrllimited='true' ctrlrange='-1 1' gainprm='390' biastype="affine" biasprm='0 0 -66'/>

  <general name='SOL_Right'  gear='1' tendon='SOL_Right'  ctrllimited='true' ctrlrange='-1 1' gainprm='822' biastype="affine" biasprm='0 0 -66'/>
  <general name='SOL_Left'  gear='1' tendon='SOL_Left'  ctrllimited='true' ctrlrange='-1 1' gainprm='822' biastype="affine" biasprm='0 0 -66'/>

  <general name='RF_Right'   gear='1' tendon='RF_Right'   ctrllimited='true' ctrlrange='-1 1' gainprm='720' biastype="affine" biasprm='0 0 -100'/>
  <general name='RF_Left'   gear='1' tendon='RF_Left'   ctrllimited='true' ctrlrange='-1 1' gainprm='720' biastype="affine" biasprm='0 0 -100'/>

  <general name='BF_Right'   gear='1' tendon='BF_Right'   ctrllimited='true' ctrlrange='-1 1' gainprm='804' biastype="affine" biasprm='0 0 -91'/>
  <general name='BF_Left'   gear='1' tendon='BF_Left'   ctrllimited='true' ctrlrange='-1 1' gainprm='804' biastype="affine" biasprm='0 0 -91'/>

  <general name='GAS_Right'  gear='1' tendon='GAS_Right'  ctrllimited='true' ctrlrange='-1 1' gainprm='720' biastype="affine" biasprm='0 0 -91'/>
  <general name='GAS_Left'  gear='1' tendon='GAS_Left'  ctrllimited='true' ctrlrange='-1 1' gainprm='720' biastype="affine" biasprm='0 0 -91'/>
</actuator>

<keyframe>
    <key time="0" qpos="0 0 0 0 0 0 0 0 0 0 0 0 0 0 0 0 0 0" />
</keyframe>

</mujoco>
