<mujoco model="Murdoc">

    <compiler inertiafromgeom='true' angle='degree'/>
    <option gravity='0 0 0'/>
    <asset>
		<!-- Sets sky rendering
		-->
        <texture type="skybox" builtin="gradient" width="100" height="100" rgb1="0 0 0"
            rgb2="0 0 0"/>
		<!-- Not clear to me where this is used yet
		-->
        <texture name="texgeom" type="cube" builtin="flat" mark="cross" width="127" height="1278"
            rgb1="0.1 0.8 0.1" rgb2="0.8 0.6 0.4" markrgb="1 1 1" random="0.01"/>
		<!-- Sets floor rendering
		-->
        <texture name="texplane" type="2d" builtin="checker" rgb1=".2 .3 .4" rgb2=".1 0.15 0.2"
            width="1000" height="1000"/>
        <texture name='bone_texture' type="cube" file="C:/Users/Radu/Documents/GitHub/Proprio-Prosthetics-Model/Version-3-0/Resources/Murdoc/Bone.png"/>
		<!-- Create materials based on textures above
		-->
        <material name='MatPlane' reflectance='0.5' texture="texplane"/>
        <material name='geom' texture="texgeom" texuniform="true"/>
        <material name='bone' texture='bone_texture' reflectance='0' texuniform='true' specular='0' shininess='0'/>

        <mesh file="C:/Users/Radu/Documents/GitHub/Proprio-Prosthetics-Model/Version-3-0/Resources/Murdoc/Pelvis.stl" scale='1e-3 1e-3 1e-3' />
        <mesh file="C:/Users/Radu/Documents/GitHub/Proprio-Prosthetics-Model/Version-3-0/Resources/Murdoc/Femur_Left.stl" scale='1e-3 1e-3 1e-3' />
        <mesh file="C:/Users/Radu/Documents/GitHub/Proprio-Prosthetics-Model/Version-3-0/Resources/Murdoc/Femur_Right.stl" scale='1e-3 1e-3 1e-3' />
        <mesh file="C:/Users/Radu/Documents/GitHub/Proprio-Prosthetics-Model/Version-3-0/Resources/Murdoc/Shin_Left.stl" scale='1e-3 1e-3 1e-3' />
        <mesh file="C:/Users/Radu/Documents/GitHub/Proprio-Prosthetics-Model/Version-3-0/Resources/Murdoc/Shin_Right.stl" scale='1e-3 1e-3 1e-3' />
        <mesh file="C:/Users/Radu/Documents/GitHub/Proprio-Prosthetics-Model/Version-3-0/Resources/Murdoc/Foot_Left.stl" scale='1e-3 1e-3 1e-3' />
        <mesh file="C:/Users/Radu/Documents/GitHub/Proprio-Prosthetics-Model/Version-3-0/Resources/Murdoc/Foot_Right.stl" scale='1e-3 1e-3 1e-3' />

    </asset>

	<default>
    <site size='
      0.5e-3 0.5e-3 0.5e-3' rgba='1 0 0 0'/>

    <default class='Hip:x'>
      <joint type='hinge' axis='0 1 0' ref='0' range='-40 150' limited='true' armature='0.0001' stiffness='0' springref='0'/>
		</default>
		<default class='Hip:y'>
            <joint type='hinge' axis='0 1 0' range='-10 10' damping='5' limited='true' stiffness='0' armature='0.0080' />
		</default>
		<default class='Hip:z'>
            <joint type='hinge' axis='0 0 1' range='-60 60' damping='5' limited='true' stiffness='0' armature='0.0080' />
		</default>
		<default class = 'Knee:x'>
			<joint type='hinge' axis='1 0 0' range='-90  70' limited='true'  armature='0.0006'  stiffness='0' springref='0'/>
		</default>
		<default class = 'Knee:y'>
			<joint type='hinge' axis='1 0 0' range='-120 40' limited='true'  armature='0.0006'  stiffness='0' springref='0'/>
		</default>
		<default class = 'Ankle:x'>
			<joint type='hinge' axis='1 0 0' pos='0 0 0' range='-60 120' limited='true'  armature='0.0006' stiffness='0' springref='0'/>
		</default>
		<default class = 'Ankle:y'>
			<joint type='hinge' axis='0 1 0' pos='0 0 0' range='-60 120' limited='true'  armature='0.0006' stiffness='0' springref='0'/>
		</default>
	</default>

	<worldbody>
    <light directional='true' diffuse='1 1 1' specular='0 0 0' pos='0 0 40.5' dir='0 1 0'/>

    <body name='Lower_Body' pos='0 0 0' euler='0 0 0'>

    <body name='Pelvis' pos='0 0 0' euler='0 0 0'>
    <joint name='World:xt' type='slide' axis='1 0 0' pos='0 0 0$' ref='0.0563597' limited='false' />
    <joint name='World:yt' type='slide' axis='0 1 0' pos='0 0 0$' ref='0.12496600000000001' limited='false' />
    <joint name='World:zt' type='slide' axis='0 0 1' pos='0 0 0$' ref='-0.18002500000000002' limited='false' />

    <joint name='World:x' type='hinge' axis='1 0 0' pos='0.0563597	0.12496600000000001	-0.18002500000000002' ref='185' limited='false'  />
    <joint name='World:y' type='hinge' axis='0 1 0' pos='0.0563597	0.12496600000000001	-0.18002500000000002' ref='10' limited='false'  />
    <joint name='World:z' type='hinge' axis='0 0 1' pos='0.0563597	0.12496600000000001	-0.18002500000000002' ref='0' limited='false'  />

     <site name="BF_Pelvis_Left" pos='0.0846852	0.160661	-0.0648937' rgba='1 0 0 0'/>
     <site name="RF_Pelvis_Left" pos='0.0778304	0.15799600000000003	-0.147005' rgba='1 0 0 0'/>
     <site name="GMED_Pelvis_Left" pos='0.051607900000000005	0.155553	-0.192365' rgba='1 0 0 0'/>
     <site name="IL_Pelvis_Left" pos='0.066193	0.161373	-0.18102200000000002' rgba='1 0 0 0'/>

     <site name="GMED_Pelvis_Right" pos='0.051607900000000005	0.155553	-0.192365' rgba='0 0 1 0'/>
     <site name="IL_Pelvis_Right" pos='0.066193	0.161373	-0.18102200000000002' rgba='0 0 1 0'/>
     <site name="RF_Pelvis_Right" pos='0.0778304	0.15799600000000003	-0.147005' rgba='0 0 1 0'/>
     <site name="BF_Pelvis_Right" pos='0.0846852	0.160661	-0.0648937' rgba='0 0 1 0'/>

     <site name="C_Right" group='1' pos='0.0310231	0.167978	-0.20496099999999998' rgba='1 1 1 1' size='5e-3'/>
     <site name="C_Left" group='1' pos='0.0223632	0.09738930000000001	-0.205471' rgba='1 1 1 1' size='5e-3'/>

     <geom type='mesh' mesh='Pelvis' density='1' pos='0 0 0' euler='0 0 0' rgba='0.651 0.623 0.572 1'/>

      <body name='GT_Holder_Right' pos='0 0 0' euler='0 0 0'>
        <site name="GT_Right" group='1' pos='0.0814642	0.18958900000000004	-0.11208200000000001' rgba='1 1 0 1' size='5e-3'/>
      </body>

    <body name='Leg_Right' pos='0 0 0' euler='0 0 0'>

      <joint name='Hip_Right:x' class='Hip:x' axis='-0.0073147	-0.016036	-0.008204' ref = '0' pos='0.0826091	0.157705	-0.11688899999999999'/>
      <joint name='Hip_Right:y' class='Hip:y' axis='0.000844	-0.001969	0.005925' ref = '-10' pos='0.0826091	0.157705	-0.11688899999999999'/>
      <joint name='Hip_Right:z' class='Hip:z' axis='-0.0078502	-8.4e-05	0.000232' ref = '0' pos='0.0826091	0.157705	-0.11688899999999999'/>

  	  <geom type='mesh' mesh='Femur_Right' density='1' pos='0 0 0' euler='0 0 0' rgba='0.651 0.623 0.572 1'/>

      <site name="GMED_Femur_Right" pos='0.0731469	0.179226	-0.108311' rgba='0 0 1 0'/>

      <site name="IL_Femur_Right" pos='0.10490899999999999	0.160921	-0.103008' rgba='0 0 1 0'/>
      <site name="IL_Front_Right" pos='0.10490899999999999	0.160921	-0.103008' rgba='0 0 1 0'/>

      <site name="VAS_Femur_Right" pos='0.15849000000000002	0.159111	-0.136153' rgba='0 0 1 0'/>
      <site name="GAS_Femur_Right" pos='0.242951	0.141299	-0.133344' rgba='0 0 1 0'/>

      <site name="K_Right" pos='0.26711700000000005	0.14675100000000002	-0.158053' rgba='1 0 0 1' size='5e-3'/>

  	  <body name='Shin_Right' pos='0 0 0' euler='0 0 0'>

          <geom type='mesh' mesh='Shin_Right' density='1' pos='0 0 0' euler='0 0 0' rgba='0.651 0.623 0.572 1'/>

          <site name="VAS_Tibia_Right" pos='0.227972	0.146542	-0.157237' rgba='0 0 1 0'/>
          <site name="TA_Tibia_Right" pos='0.343832	0.127757	-0.134737' rgba='0 0 1 0'/>
          <site name="SOL_Tibia_Right" pos='0.277582	0.152171	-0.12554600000000002' rgba='0 0 1 0'/>
          <site name="RF_Tibia_Right" pos='0.23261	0.14416299999999999	-0.159571' rgba='0 0 1 0'/>
          <site name="BF_Tibia_Right" pos='0.27140800000000004	0.15383600000000003	-0.126231' rgba='0 0 1 0'/>

          <joint name='Knee_Right:x' class='Knee:x' axis='-0.001537	-0.012808	0.0' ref='-60' pos='0.261764	0.141711	-0.14281200000000002'/>

  				<body name='Foot_Right' pos='0 0 0' >

            <geom type='mesh' mesh='Foot_Right' density='1' pos='0 0 0' euler='0 0 0' rgba='0.651 0.623 0.572 1'/>

            <site name="M_Right" pos='0.454192	0.142859	-0.096663' rgba='0.5 0.5 0.5 1' size='5e-3'/>
            <site name="MT_Right" pos='0.534378	0.12728	-0.116801' rgba='0 0 1 1' size='5e-3'/>
            <site name="T_Right" pos='0.568988	0.109595	-0.113604' rgba='0 1 1 1' size='5e-3'/>

            <site name="TA_Ankle_Right" pos='0.464477	0.102348	-0.0964599' rgba='0 0 1 0'/>
            <site name="SOL_Ankle_Right" pos='0.43153500000000006	0.128441	-0.0745976' rgba='0 0 1 0'/>
            <site name="GAS_Ankle_Right" pos='0.429856	0.126789	-0.076244' rgba='0 0 1 0'/>

            <joint name='Ankle_Right:x' class='Ankle:x' axis='-0.000838	-0.008659	0.0'  ref='60' pos='0.446505	0.130104	-0.10443700000000002'/>
            <joint name='Ankle_Right:y' class='Ankle:y' axis='-0.000226	-0.000533	0.005476'  pos='0.446505	0.130104	-0.10443700000000002'/>

  				</body>
  				<!-- End foot
  				-->
  	</body>
  	<!-- End shin
  	-->
  </body>
  <!-- End leg
  -->

      <body name='GT_Holder_Left' pos='0 0 0' euler='0 0 0'>
        <site name="GT_Left" group='1' pos='0.0633843	0.047944600000000004	-0.116957' rgba='1 1 0 1' size='5e-3'/>
      </body>

      <body name='Leg_Left' pos='0 0 0' euler='0 0 0'>

        <joint name='Hip_Left:x' class='Hip:x' axis='-0.001688	0.013785	-0.011' ref = '-17' pos='0.069949	0.07611799999999999	-0.12374600000000001'/>
        <joint name='Hip_Left:y' class='Hip:y' axis='-0.0002814	9.99999999891e-08	0.007319' ref = '0' pos='0.069949	0.07611799999999999	-0.12374600000000001'/>
        <joint name='Hip_Left:z' class='Hip:z' axis='-0.0205103	-0.0001158	9.99999999999e-06' ref = '30' pos='0.069949	0.07611799999999999	-0.12374600000000001'/>

    	  <geom type='mesh' mesh='Femur_Left' density='1' pos='0 0 0' euler='0 0 0' rgba='0.651 0.623 0.572 1'/>

        <site name="GMED_Femur_Left" pos='0.0731469	0.179226	-0.108311' rgba='0 0 1 0'/>

        <site name="IL_Femur_Left" pos='0.10490899999999999	0.160921	-0.103008' rgba='0 0 1 0'/>
        <site name="IL_Front_Left" pos='0.10490899999999999	0.160921	-0.103008' rgba='0 0 1 0'/>

        <site name="VAS_Femur_Left" pos='0.15849000000000002	0.159111	-0.136153' rgba='0 0 1 0'/>
        <site name="GAS_Femur_Left" pos='0.242951	0.141299	-0.133344' rgba='0 0 1 0'/>

        <site name="K_Left" pos='0.27113400000000004	0.0897635	-0.10431399999999999' rgba='1 0 0 1' size='5e-3'/>

    	  <body name='Shin_Left' pos='0 0 0' euler='0 0 0'>

            <geom type='mesh' mesh='Shin_Left' density='1' pos='0 0 0' euler='0 0 0' rgba='0.651 0.623 0.572 1'/>

            <site name="VAS_Tibia_Left" pos='0.227972	0.146542	-0.157237' rgba='0 0 1 0'/>
            <site name="TA_Tibia_Left" pos='0.343832	0.127757	-0.134737' rgba='0 0 1 0'/>
            <site name="SOL_Tibia_Left" pos='0.277582	0.152171	-0.12554600000000002' rgba='0 0 1 0'/>
            <site name="RF_Tibia_Left" pos='0.23261	0.14416299999999999	-0.159571' rgba='0 0 1 0'/>
            <site name="BF_Tibia_Left" pos='0.27140800000000004	0.15383600000000003	-0.126231' rgba='0 0 1 0'/>

            <joint name='Knee_Left:x' class='Knee:x' axis='0.0	0.0135896	-0.0059711'  ref='60' pos='0.255763	0.0947011	-0.08999760000000001'/>

    				<body name='Foot_Left' pos='0 0 0' >

              <geom type='mesh' mesh='Foot_Left' density='1' pos='0 0 0' euler='0 0 0' rgba='0.651 0.623 0.572 1'/>

              <site name="M_Left" pos='0.39995800000000004	0.11373200000000001	0.0284587' rgba='0.5 0.5 0.5 1' size='5e-3'/>
              <site name="MT_Left" pos='0.477032	0.10137299999999999	0.0469846' rgba='0 0 1 1' size='5e-3'/>
              <site name="T_Left" pos='0.513024	0.10679799999999999	0.0571901' rgba='0 1 1 1' size='5e-3'/>

              <site name="TA_Ankle_Left" pos='0.464477	0.102348	-0.0964599' rgba='0 0 1 0'/>
              <site name="SOL_Ankle_Left" pos='0.43153500000000006	0.128441	-0.0745976' rgba='0 0 1 0'/>
              <site name="GAS_Ankle_Left" pos='0.429856	0.126789	-0.076244' rgba='0 0 1 0'/>

              <joint name='Ankle_Left:x' class='Ankle:x' axis='-0.00226	0.006401	-0.003'  ref='-60' pos='0.40128500000000006	0.12106200000000002	0.018296399999999997'/>
              <joint name='Ankle_Left:y' class='Ankle:y' axis='0.0	2.5e-05	0.01096965'  pos='0.40128500000000006	0.12106200000000002	0.018296399999999997'/>
    				</body>
    				<!-- End foot
    				-->
    	</body>
    	<!-- End shin
    	-->
    </body>
    <!-- End leg
    -->
     </body>
     <!--
     End Pelvis
   -->

    </body>
    <!-- End Lower bod
    -->
	</worldbody>

  <tendon>
    <spatial name="IL_Left" stiffness="0" width="0.002" rgba=".95 .3 .3 0" limited="false" range="0 0.33">
        <site site='IL_Pelvis_Left'/>
        <site site='IL_Femur_Left'/>
    </spatial>

    <spatial name="GMED_Left" stiffness="0" width="0.002" rgba=".95 .3 .3 0" limited="false" range="0 0.33">
      <site site='GMED_Pelvis_Left'/>
      <site site='GMED_Femur_Left'/>
    </spatial>

    <spatial name='VAS_Left' stiffness="0" width="0.002" rgba=".95 .3 .3 0" limited="false" range="0 0.33">
      <site site='VAS_Femur_Left'/>
      <site site='VAS_Tibia_Left'/>
    </spatial>

    <spatial name='TA_Left' stiffness="0" width="0.002" rgba=".95 .3 .3 0" limited="false" range="0 0.33">
      <site site='TA_Tibia_Left'/>
      <site site='TA_Ankle_Left'/>
    </spatial>

    <spatial name='SOL_Left' stiffness="0" width="0.002" rgba=".95 .3 .3 0" limited="false" range="0 0.33">
      <site site='SOL_Tibia_Left'/>
      <site site='SOL_Ankle_Left'/>
    </spatial>

    <spatial name='RF_Left' stiffness="0" width="0.002" rgba=".95 .3 .3 0" limited="false" range="0 0.33">
      <site site='RF_Pelvis_Left'/>
      <site site='RF_Tibia_Left'/>
    </spatial>

    <spatial name='BF_Left' stiffness="0" width="0.002" rgba=".95 .3 .3 0" limited="false" range="0 0.33">
      <site site='BF_Pelvis_Left'/>
      <site site='BF_Tibia_Left'/>
    </spatial>

    <spatial name='GAS_Left' stiffness="0" width="0.002" rgba=".95 .3 .3 0" limited="false" range="0 0.33">
      <site site='GAS_Femur_Left'/>
      <site site='GAS_Ankle_Left'/>
    </spatial>
      <spatial name="IL_Right" stiffness="0" width="0.002" rgba=".95 .3 .3 0" limited="false" range="0 0.33">
          <site site='IL_Pelvis_Right'/>
          <site site='IL_Femur_Right'/>
      </spatial>

      <spatial name="GMED_Right" stiffness="0" width="0.002" rgba=".95 .3 .3 0" limited="false" range="0 0.33">
        <site site='GMED_Pelvis_Right'/>
        <site site='GMED_Femur_Right'/>
      </spatial>

      <spatial name='VAS_Right' stiffness="0" width="0.002" rgba=".95 .3 .3 0" limited="false" range="0 0.33">
        <site site='VAS_Femur_Right'/>
        <site site='VAS_Tibia_Right'/>
      </spatial>

      <spatial name='TA_Right' stiffness="0" width="0.002" rgba=".95 .3 .3 0" limited="false" range="0 0.33">
        <site site='TA_Tibia_Right'/>
        <site site='TA_Ankle_Right'/>
      </spatial>

      <spatial name='SOL_Right' stiffness="0" width="0.002" rgba=".95 .3 .3 0" limited="false" range="0 0.33">
        <site site='SOL_Tibia_Right'/>
        <site site='SOL_Ankle_Right'/>
      </spatial>

      <spatial name='RF_Right' stiffness="0" width="0.002" rgba=".95 .3 .3 0" limited="false" range="0 0.33">
        <site site='RF_Pelvis_Right'/>
        <site site='RF_Tibia_Right'/>
      </spatial>

      <spatial name='BF_Right' stiffness="0" width="0.002" rgba=".95 .3 .3 0" limited="false" range="0 0.33">
        <site site='BF_Pelvis_Right'/>
        <site site='BF_Tibia_Right'/>
      </spatial>

      <spatial name='GAS_Right' stiffness="0" width="0.002" rgba=".95 .3 .3 0" limited="false" range="0 0.33">
        <site site='GAS_Femur_Right'/>
        <site site='GAS_Ankle_Right'/>
      </spatial>
</tendon>

<actuator>
  <general name='IL_Right'   gear='1' tendon='IL_Right'   ctrllimited='true' ctrlrange='-1 1' gainprm='642' biastype="affine" biasprm='0 0 -91'/>
  <general name='IL_Left'   gear='1' tendon='IL_Left'   ctrllimited='true' ctrlrange='-1 1' gainprm='642' biastype="affine" biasprm='0 0 -91'/>

  <general name='GMED_Right' gear='1' tendon='GMED_Right' ctrllimited='true' ctrlrange='-1 1' gainprm='738' biastype="affine" biasprm='0 0 -91'/>
  <general name='GMED_Left' gear='1' tendon='GMED_Left' ctrllimited='true' ctrlrange='-1 1' gainprm='738' biastype="affine" biasprm='0 0 -91'/>

  <general name='VAS_Right'  gear='1' tendon='VAS_Right'  ctrllimited='true' ctrlrange='-1 1' gainprm='2514' biastype="affine" biasprm='0 0 -100'/>
  <general name='VAS_Left'  gear='1' tendon='VAS_Left'  ctrllimited='true' ctrlrange='-1 1' gainprm='2514' biastype="affine" biasprm='0 0 -100'/>

  <general name='TA_Right'   gear='1' tendon='TA_Right'   ctrllimited='true' ctrlrange='-1 1' gainprm='390' biastype="affine" biasprm='0 0 -66'/>
  <general name='TA_Left'   gear='1' tendon='TA_Left'   ctrllimited='true' ctrlrange='-1 1' gainprm='390' biastype="affine" biasprm='0 0 -66'/>

  <general name='SOL_Right'  gear='1' tendon='SOL_Right'  ctrllimited='true' ctrlrange='-1 1' gainprm='822' biastype="affine" biasprm='0 0 -66'/>
  <general name='SOL_Left'  gear='1' tendon='SOL_Left'  ctrllimited='true' ctrlrange='-1 1' gainprm='822' biastype="affine" biasprm='0 0 -66'/>

  <general name='RF_Right'   gear='1' tendon='RF_Right'   ctrllimited='true' ctrlrange='-1 1' gainprm='720' biastype="affine" biasprm='0 0 -100'/>
  <general name='RF_Left'   gear='1' tendon='RF_Left'   ctrllimited='true' ctrlrange='-1 1' gainprm='720' biastype="affine" biasprm='0 0 -100'/>

  <general name='BF_Right'   gear='1' tendon='BF_Right'   ctrllimited='true' ctrlrange='-1 1' gainprm='804' biastype="affine" biasprm='0 0 -91'/>
  <general name='BF_Left'   gear='1' tendon='BF_Left'   ctrllimited='true' ctrlrange='-1 1' gainprm='804' biastype="affine" biasprm='0 0 -91'/>

  <general name='GAS_Right'  gear='1' tendon='GAS_Right'  ctrllimited='true' ctrlrange='-1 1' gainprm='720' biastype="affine" biasprm='0 0 -91'/>
  <general name='GAS_Left'  gear='1' tendon='GAS_Left'  ctrllimited='true' ctrlrange='-1 1' gainprm='720' biastype="affine" biasprm='0 0 -91'/>
</actuator>

<keyframe>
    <key time="0" qpos="0 0 0 0 0 0 0 0 0 0 0 0 0 0 0 0 0 0" />
</keyframe>

</mujoco>
