<mujoco model="Murdoc">

    <compiler inertiafromgeom='true' angle='degree'/>
    <option gravity='0 0 0'/>
    <asset>
		<!-- Sets sky rendering
		-->
        <texture type="skybox" builtin="gradient" width="100" height="100" rgb1="0 0 0"
            rgb2="0 0 0"/>
		<!-- Not clear to me where this is used yet
		-->
        <texture name="texgeom" type="cube" builtin="flat" mark="cross" width="127" height="1278"
            rgb1="0.1 0.8 0.1" rgb2="0.8 0.6 0.4" markrgb="1 1 1" random="0.01"/>
		<!-- Sets floor rendering
		-->
        <texture name="texplane" type="2d" builtin="checker" rgb1=".2 .3 .4" rgb2=".1 0.15 0.2"
            width="1000" height="1000"/>
      
        <texture name='bone_texture' type="cube" file="C:\Users\Radu\Documents\GitHub\Proprio-Prosthetics-Model\Version-3-0/Resources/Murdoc/Bone.png"/>
		<!-- Create materials based on textures above
		-->
        <material name='MatPlane' reflectance='0.5' texture="texplane"/>
        <material name='geom' texture="texgeom" texuniform="true"/>
        <material name='bone' texture='bone_texture' reflectance='0' texuniform='true' specular='0' shininess='0'/>

        <mesh file="C:\Users\Radu\Documents\GitHub\Proprio-Prosthetics-Model\Version-3-0/Resources/Murdoc/Pelvis.stl" scale='0.0011 0.0011 0.0011' />
        <mesh file="C:\Users\Radu\Documents\GitHub\Proprio-Prosthetics-Model\Version-3-0/Resources/Murdoc/Femur_Left.stl" scale='0.0011 0.0011 0.0011' />
        <mesh file="C:\Users\Radu\Documents\GitHub\Proprio-Prosthetics-Model\Version-3-0/Resources/Murdoc/Femur_Right.stl" scale='0.0011 0.0011 0.0011' />
        <mesh file="C:\Users\Radu\Documents\GitHub\Proprio-Prosthetics-Model\Version-3-0/Resources/Murdoc/Shin_Left.stl" scale='0.0011 0.0011 0.0011' />
        <mesh file="C:\Users\Radu\Documents\GitHub\Proprio-Prosthetics-Model\Version-3-0/Resources/Murdoc/Shin_Right.stl" scale='0.0011 0.0011 0.0011' />
        <mesh file="C:\Users\Radu\Documents\GitHub\Proprio-Prosthetics-Model\Version-3-0/Resources/Murdoc/Foot_Left.stl" scale='0.0011 0.0011 0.0011' />
        <mesh file="C:\Users\Radu\Documents\GitHub\Proprio-Prosthetics-Model\Version-3-0/Resources/Murdoc/Foot_Right.stl" scale='0.0011 0.0011 0.0011' />

    </asset>

	<default>
    <site size='0.5e-3 0.5e-3 0.5e-3' rgba='1 0 0 0'/>

    <default class='Hip:x'>
      <joint type='hinge' axis='0 1 0' ref='0' range='-60 90' limited='true' armature='0.0001' stiffness='0' springref='0'/>
		</default>
		<default class='Hip:y'>
            <joint type='hinge' axis='0 1 0' range='-15 15' damping='5' limited='true' stiffness='0' armature='0.0080' />
		</default>
		<default class='Hip:z'>
            <joint type='hinge' axis='0 0 1' range='-15 15' damping='5' limited='true' stiffness='0' armature='0.0080' />
		</default>
		<default class = 'Knee:x'>
			<joint type='hinge' axis='1 0 0' range='-90  70' limited='true'  armature='0.0006'  stiffness='0' springref='0'/>
		</default>
		<default class = 'Knee:y'>
			<joint type='hinge' axis='1 0 0' range='-120 40' limited='true'  armature='0.0006'  stiffness='0' springref='0'/>
		</default>
		<default class = 'Ankle:x'>
			<joint type='hinge' axis='1 0 0' pos='0 0 0' range='-60 120' limited='true'  armature='0.0006' stiffness='0' springref='0'/>
		</default>
		<default class = 'Ankle:y'>
			<joint type='hinge' axis='0 1 0' pos='0 0 0' range='-60 60' limited='true'  armature='0.0006' stiffness='0' springref='0'/>
		</default>
	</default>

	<worldbody>
    <light directional='true' diffuse='1 1 1' specular='0 0 0' pos='0 0 40.5' dir='0 1 0'/>

    <body name='Lower_Body' pos='0 0 0' euler='0 0 0'>

    <body name='Pelvis' pos='0 0 0' euler='0 0 0'>
    <camera name = 'Sagittal_Left' mode = 'fixed' pos = '3e-1 -5e-1 -2e-1' euler = '90 0 180'/>

    <joint name='World:xt' type='slide' axis='1 0 0' pos='0 0 0' ref='0.06199567' limited='false' />
    <joint name='World:yt' type='slide' axis='0 1 0' pos='0 0 0' ref='0.13746260000000002' limited='false' />
    <joint name='World:zt' type='slide' axis='0 0 1' pos='0 0 0' ref='-0.19802750000000002' limited='false' />

    <joint name='World:x' type='hinge' axis='1 0 0' pos='0.06199567	0.13746260000000002	-0.19802750000000002' ref='185' limited='false'  />
    <joint name='World:y' type='hinge' axis='0 1 0' pos='0.06199567	0.13746260000000002	-0.19802750000000002' ref='10' limited='false'  />
    <joint name='World:z' type='hinge' axis='0 0 1' pos='0.06199567	0.13746260000000002	-0.19802750000000002' ref='0' limited='false'  />

     <site name="BF_Pelvis_Left" pos='0.07541567000000002	0.07732472	-0.08395585' rgba='1 0 0 0'/>
     <site name="RF_Pelvis_Left" pos='0.0764522	0.0946209	-0.16296610000000003' rgba='1 0 0 0'/>
     <site name="GMED_Pelvis_Left" pos='0.049623860000000006	0.10116183000000001	-0.22827200000000003' rgba='1 0 0 0'/>
     <site name="IL_Pelvis_Left" pos='0.09443148000000001	0.09588931	-0.1390752' rgba='1 0 0 0'/>

     <site name="GMED_Pelvis_Right" pos='0.05741384000000001	0.17560510000000001	-0.22142340000000002' rgba='0 0 1 0'/>
     <site name="IL_Pelvis_Right" pos='0.10638243	0.15780490000000003	-0.13306700000000002' rgba='0 0 1 0'/>
     <site name="RF_Pelvis_Right" pos='0.08400359	0.17506610000000003	-0.16586789999999998' rgba='0 0 1 0'/>
     <site name="BF_Pelvis_Right" pos='0.09202149000000001	0.17616060000000003	-0.07276973' rgba='0 0 1 0'/>

     <site name="C_Right" group='1' pos='0.03412541	0.1847758	-0.2254571' rgba='1 1 1 1' size='5e-3'/>
     <site name="C_Left" group='1' pos='0.02459952	0.10712823000000002	-0.2260181' rgba='1 1 1 1' size='5e-3'/>

     <geom type='mesh' mesh='Pelvis' density='1' pos='0 0 0' euler='0 0 0' rgba='0.651 0.623 0.572 1'/>

      <body name='GT_Holder_Right' pos='0 0 0' euler='0 0 0'>
        <site name="GT_Right" group='1' pos='0.08961062000000002	0.20854790000000004	-0.12329020000000002' rgba='1 1 0 1' size='5e-3'/>
      </body>

    <body name='Leg_Right' pos='0 0 0' euler='0 0 0'>

      <joint name='Hip_Right:x' class='Hip:x' axis='0.00074338	-0.0152141	0.0002453' ref = '0' pos='0.09087001	0.17541700000000002	-0.12417790000000001'/>
      <joint name='Hip_Right:y' class='Hip:y' axis='0.0009284	-0.0002244	0.0109175' ref = '-10' pos='0.09087001	0.17541700000000002	-0.12417790000000001'/>
      <joint name='Hip_Right:z' class='Hip:z' axis='-0.00758516	0.0006831	0.0004257' ref = '0' pos='0.09087001	0.17541700000000002	-0.12417790000000001'/>

  	  <geom type='mesh' mesh='Femur_Right' density='1' pos='0 0 0' euler='0 0 0' rgba='0.651 0.623 0.572 1'/>

      <site name="GMED_Femur_Right" pos='0.07976562000000001	0.19600350000000002	-0.12033670000000002' rgba='0 0 1 0'/>

      <site name="IL_Femur_Right" pos='0.11386320000000001	0.17627610000000002	-0.1153823' rgba='0 0 1 0'/>
      <site name="IL_Front_Right" pos='$IL_Front_Right:x$	$IL_Front_Right:y$	$IL_Front_Right:z$' rgba='0 0 1 0'/>

      <site name="VAS_Femur_Right" pos='0.18480770000000002	0.1731312	-0.1498046' rgba='0 0 1 0'/>
      <site name="GAS_Femur_Right" pos='0.2800446	0.1584583	-0.14959010000000003' rgba='0 0 1 0'/>

      <site name="K_Right" pos='0.29382870000000005	0.16142610000000002	-0.17385830000000002' rgba='1 0 0 1' size='5e-3'/>

  	  <body name='Shin_Right' pos='0 0 0' euler='0 0 0'>

          <geom type='mesh' mesh='Shin_Right' density='1' pos='0 0 0' euler='0 0 0' rgba='0.651 0.623 0.572 1'/>

          <site name="VAS_Tibia_Right" pos='0.26958360000000003	0.1572395	-0.1768569' rgba='0 0 1 0'/>
          <site name="TA_Tibia_Right" pos='0.3731222	0.1474473	-0.1525128' rgba='0 0 1 0'/>
          <site name="SOL_Tibia_Right" pos='0.30460210000000004	0.16444450000000002	-0.1423906' rgba='0 0 1 0'/>
          <site name="RF_Tibia_Right" pos='0.269885	0.16199370000000002	-0.1770065' rgba='0 0 1 0'/>
          <site name="BF_Tibia_Right" pos='0.3047671	0.1695067	-0.1462747' rgba='0 0 1 0'/>

          <joint name='Knee_Right:x' class='Knee:x' axis='-0.0016907	-0.0140888	0.0' ref='-60' pos='0.28794040000000004	0.15588210000000002	-0.15709320000000002'/>

  				<body name='Foot_Right' pos='0 0 0' >

            <geom type='mesh' mesh='Foot_Right' density='1' pos='0 0 0' euler='0 0 0' rgba='0.651 0.623 0.572 1'/>

            <site name="M_Right" pos='0.4996112	0.15714490000000003	-0.1063293' rgba='0.5 0.5 0.5 1' size='5e-3'/>
            <site name="MT_Right" pos='0.5878158000000001	0.14000800000000002	-0.12848110000000001' rgba='0 0 1 1' size='5e-3'/>
            <site name="T_Right" pos='0.6258868000000001	0.12055450000000001	-0.1249644' rgba='0 1 1 1' size='5e-3'/>

            <site name="TA_Ankle_Right" pos='0.5308237	0.1136993	-0.11346060000000001' rgba='0 0 1 0'/>
            <site name="SOL_Ankle_Right" pos='0.48338400000000004	0.1476398	-0.09132299' rgba='0 0 1 0'/>
            <site name="GAS_Ankle_Right" pos='0.4816471	0.1477146	-0.09284858' rgba='0 0 1 0'/>

            <joint name='Ankle_Right:x' class='Ankle:x' axis='-0.0059554	-0.0165869	-0.00123706'  ref='60' pos='0.4969162	0.1384141	-0.10952469'/>
            <joint name='Ankle_Right:y' class='Ankle:y' axis='-0.0043725	-0.0032538	-0.01796993'  pos='0.4969162	0.1384141	-0.10952469'/>

  				</body>
  				<!-- End foot
  				-->
  	</body>
  	<!-- End shin
  	-->
  </body>
  <!-- End leg
  -->

      <body name='GT_Holder_Left' pos='0 0 0' euler='0 0 0'>
        <site name="GT_Left" group='1' pos='0.06972273000000001	0.052739060000000004	-0.1286527' rgba='1 1 0 1' size='5e-3'/>
      </body>

      <body name='Leg_Left' pos='0 0 0' euler='0 0 0'>

        <joint name='Hip_Left:x' class='Hip:x' axis='0.00126005	-0.01726747	-0.0004301' ref = '10' pos='0.07704499	0.08609337	-0.1343617'/>
        <joint name='Hip_Left:y' class='Hip:y' axis='0.0	-0.00012276	0.0093247' ref = '10' pos='0.07704499	0.08609337	-0.1343617'/>
        <joint name='Hip_Left:z' class='Hip:z' axis='-0.01782528	-0.00145189	-0.0012419' ref = '30' pos='0.07704499	0.08609337	-0.1343617'/>

    	  <geom type='mesh' mesh='Femur_Left' density='1' pos='0 0 0' euler='0 0 0' rgba='0.651 0.623 0.572 1'/>

        <site name="GMED_Femur_Left" pos='0.06510064	0.06600594	-0.1287946' rgba='0 0 1 0'/>

        <site name="IL_Femur_Left" pos='0.09909427000000001	0.08435284	-0.1156133' rgba='0 0 1 0'/>
        <site name="IL_Front_Left" pos='$IL_Front_Left:x$	$IL_Front_Left:y$	$IL_Front_Left:z$' rgba='0 0 1 0'/>

        <site name="VAS_Femur_Left" pos='0.1872123	0.08587986	-0.1304578' rgba='0 0 1 0'/>
        <site name="GAS_Femur_Left" pos='0.2826054	0.10399796	-0.09229473000000002' rgba='0 0 1 0'/>

        <site name="K_Left" pos='0.29824740000000005	0.09873985	-0.1147454' rgba='1 0 0 1' size='5e-3'/>

    	  <body name='Shin_Left' pos='0 0 0' euler='0 0 0'>

            <geom type='mesh' mesh='Shin_Left' density='1' pos='0 0 0' euler='0 0 0' rgba='0.651 0.623 0.572 1'/>

            <site name="VAS_Tibia_Left" pos='0.27771809999999997	0.10049798000000001	-0.1228139' rgba='0 0 1 0'/>
            <site name="TA_Tibia_Left" pos='0.3682492	0.1155319	-0.05739701' rgba='0 0 1 0'/>
            <site name="SOL_Tibia_Left" pos='0.3000371	0.09832317	-0.07756111' rgba='0 0 1 0'/>
            <site name="RF_Tibia_Left" pos='0.2768799	0.09597104	-0.1234343' rgba='0 0 1 0'/>
            <site name="BF_Tibia_Left" pos='0.2973894000000001	0.09430707	-0.08177565' rgba='0 0 1 0'/>

            <joint name='Knee_Left:x' class='Knee:x' axis='-0.00022	-0.01317129	0.00393778'  ref='-60' pos='0.2813393	0.10417121	-0.09899736'/>

    				<body name='Foot_Left' pos='0 0 0' >

              <geom type='mesh' mesh='Foot_Left' density='1' pos='0 0 0' euler='0 0 0' rgba='0.651 0.623 0.572 1'/>

              <site name="M_Left" pos='0.43995380000000006	0.12510520000000003	0.031304570000000004' rgba='0.5 0.5 0.5 1' size='5e-3'/>
              <site name="MT_Left" pos='0.5247352	0.11151029999999999	0.05168306' rgba='0 0 1 1' size='5e-3'/>
              <site name="T_Left" pos='0.5643264	0.1174778	0.06290911' rgba='0 1 1 1' size='5e-3'/>

              <site name="TA_Ankle_Left" pos='0.4713621	0.15333670000000002	0.02389673' rgba='0 0 1 0'/>
              <site name="SOL_Ankle_Left" pos='0.42997680000000005	0.14066579999999998	0.031173120000000002' rgba='0 0 1 0'/>
              <site name="GAS_Ankle_Left" pos='0.4287932	0.1393337	0.027288580000000003' rgba='0 0 1 0'/>

              <joint name='Ankle_Left:x' class='Ankle:x' axis='-0.0052096	-0.0099781	0.00348623'  ref='60' pos='0.4497625	0.1371293	0.01969682'/>
              <joint name='Ankle_Left:y' class='Ankle:y' axis='0.0028248	-0.0093918	-0.01496044'  ref='0' pos='0.4497625	0.1371293	0.01969682'/>
    				</body>
    				<!-- End foot
    				-->
    	</body>
    	<!-- End shin
    	-->
    </body>
    <!-- End leg
    -->
     </body>
     <!--
     End Pelvis
   -->

    </body>
    <!-- End Lower bod
    -->
	</worldbody>

  <tendon>
    <spatial name="IL_Left" stiffness="0" width="0.002" rgba=".95 .3 .3 1" limited="false" range="0 0.33">
        <site site='IL_Pelvis_Left'/>
        <site site='IL_Femur_Left'/>
    </spatial>

    <spatial name="GMED_Left" stiffness="0" width="0.002" rgba=".95 .3 .3 1" limited="false" range="0 0.33">
      <site site='GMED_Pelvis_Left'/>
      <site site='GMED_Femur_Left'/>
    </spatial>

    <spatial name='VAS_Left' stiffness="0" width="0.002" rgba=".95 .3 .3 1" limited="false" range="0 0.33">
      <site site='VAS_Femur_Left'/>
      <site site='VAS_Tibia_Left'/>
    </spatial>

    <spatial name='TA_Left' stiffness="0" width="0.002" rgba=".95 .3 .3 1" limited="false" range="0 0.33">
      <site site='TA_Tibia_Left'/>
      <site site='TA_Ankle_Left'/>
    </spatial>

    <spatial name='SOL_Left' stiffness="0" width="0.002" rgba=".95 .3 .3 1" limited="false" range="0 0.33">
      <site site='SOL_Tibia_Left'/>
      <site site='SOL_Ankle_Left'/>
    </spatial>

    <spatial name='RF_Left' stiffness="0" width="0.002" rgba=".95 .3 .3 1" limited="false" range="0 0.33">
      <site site='RF_Pelvis_Left'/>
      <site site='RF_Tibia_Left'/>
    </spatial>

    <spatial name='BF_Left' stiffness="0" width="0.002" rgba=".95 .3 .3 1" limited="false" range="0 0.33">
      <site site='BF_Pelvis_Left'/>
      <site site='BF_Tibia_Left'/>
    </spatial>

    <spatial name='GAS_Left' stiffness="0" width="0.002" rgba=".95 .3 .3 1" limited="false" range="0 0.33">
      <site site='GAS_Femur_Left'/>
      <site site='GAS_Ankle_Left'/>
    </spatial>
      <spatial name="IL_Right" stiffness="0" width="0.002" rgba=".95 .3 .3 1" limited="false" range="0 0.33">
          <site site='IL_Pelvis_Right'/>
          <site site='IL_Femur_Right'/>
      </spatial>

      <spatial name="GMED_Right" stiffness="0" width="0.002" rgba=".95 .3 .3 1" limited="false" range="0 0.33">
        <site site='GMED_Pelvis_Right'/>
        <site site='GMED_Femur_Right'/>
      </spatial>

      <spatial name='VAS_Right' stiffness="0" width="0.002" rgba=".95 .3 .3 1" limited="false" range="0 0.33">
        <site site='VAS_Femur_Right'/>
        <site site='VAS_Tibia_Right'/>
      </spatial>

      <spatial name='TA_Right' stiffness="0" width="0.002" rgba=".95 .3 .3 1" limited="false" range="0 0.33">
        <site site='TA_Tibia_Right'/>
        <site site='TA_Ankle_Right'/>
      </spatial>

      <spatial name='SOL_Right' stiffness="0" width="0.002" rgba=".95 .3 .3 1" limited="false" range="0 0.33">
        <site site='SOL_Tibia_Right'/>
        <site site='SOL_Ankle_Right'/>
      </spatial>

      <spatial name='RF_Right' stiffness="0" width="0.002" rgba=".95 .3 .3 1" limited="false" range="0 0.33">
        <site site='RF_Pelvis_Right'/>
        <site site='RF_Tibia_Right'/>
      </spatial>

      <spatial name='BF_Right' stiffness="0" width="0.002" rgba=".95 .3 .3 1" limited="false" range="0 0.33">
        <site site='BF_Pelvis_Right'/>
        <site site='BF_Tibia_Right'/>
      </spatial>

      <spatial name='GAS_Right' stiffness="0" width="0.002" rgba=".95 .3 .3 1" limited="false" range="0 0.33">
        <site site='GAS_Femur_Right'/>
        <site site='GAS_Ankle_Right'/>
      </spatial>
</tendon>

<actuator>
  <general name='IL_Right'   gear='1' tendon='IL_Right'   ctrllimited='true' ctrlrange='-1 1' gainprm='642' biastype="affine" biasprm='0 0 -91'/>
  <general name='IL_Left'   gear='1' tendon='IL_Left'   ctrllimited='true' ctrlrange='-1 1' gainprm='642' biastype="affine" biasprm='0 0 -91'/>

  <general name='GMED_Right' gear='1' tendon='GMED_Right' ctrllimited='true' ctrlrange='-1 1' gainprm='738' biastype="affine" biasprm='0 0 -91'/>
  <general name='GMED_Left' gear='1' tendon='GMED_Left' ctrllimited='true' ctrlrange='-1 1' gainprm='738' biastype="affine" biasprm='0 0 -91'/>

  <general name='VAS_Right'  gear='1' tendon='VAS_Right'  ctrllimited='true' ctrlrange='-1 1' gainprm='2514' biastype="affine" biasprm='0 0 -100'/>
  <general name='VAS_Left'  gear='1' tendon='VAS_Left'  ctrllimited='true' ctrlrange='-1 1' gainprm='2514' biastype="affine" biasprm='0 0 -100'/>

  <general name='TA_Right'   gear='1' tendon='TA_Right'   ctrllimited='true' ctrlrange='-1 1' gainprm='390' biastype="affine" biasprm='0 0 -66'/>
  <general name='TA_Left'   gear='1' tendon='TA_Left'   ctrllimited='true' ctrlrange='-1 1' gainprm='390' biastype="affine" biasprm='0 0 -66'/>

  <general name='SOL_Right'  gear='1' tendon='SOL_Right'  ctrllimited='true' ctrlrange='-1 1' gainprm='822' biastype="affine" biasprm='0 0 -66'/>
  <general name='SOL_Left'  gear='1' tendon='SOL_Left'  ctrllimited='true' ctrlrange='-1 1' gainprm='822' biastype="affine" biasprm='0 0 -66'/>

  <general name='RF_Right'   gear='1' tendon='RF_Right'   ctrllimited='true' ctrlrange='-1 1' gainprm='720' biastype="affine" biasprm='0 0 -100'/>
  <general name='RF_Left'   gear='1' tendon='RF_Left'   ctrllimited='true' ctrlrange='-1 1' gainprm='720' biastype="affine" biasprm='0 0 -100'/>

  <general name='BF_Right'   gear='1' tendon='BF_Right'   ctrllimited='true' ctrlrange='-1 1' gainprm='804' biastype="affine" biasprm='0 0 -91'/>
  <general name='BF_Left'   gear='1' tendon='BF_Left'   ctrllimited='true' ctrlrange='-1 1' gainprm='804' biastype="affine" biasprm='0 0 -91'/>

  <general name='GAS_Right'  gear='1' tendon='GAS_Right'  ctrllimited='true' ctrlrange='-1 1' gainprm='720' biastype="affine" biasprm='0 0 -91'/>
  <general name='GAS_Left'  gear='1' tendon='GAS_Left'  ctrllimited='true' ctrlrange='-1 1' gainprm='720' biastype="affine" biasprm='0 0 -91'/>
</actuator>

<keyframe>
    <key time="0" qpos="0 0 0 0 0 0 0 0 0 0 0 0 0 0 0 0 0 0" />
    <key time="0" qpos="0 0 0 0 0 0 -1 0 0 1 0 0 0 0 0 0 0 0" />
</keyframe>

</mujoco>
